<?xml version="1.0" ?>
<!-- =================================================================================== -->
<!-- |    This document was autogenerated by xacro from diana_v2.urdf                  | -->
<!-- |    EDITING THIS FILE BY HAND IS NOT RECOMMENDED                                 | -->
<!-- =================================================================================== -->
<!-- This URDF was automatically created by SolidWorks to URDF Exporter! Originally created by Stephen Brawner (brawner@gmail.com) 
     Commit Version: 1.5.1-0-g916b5db  Build Version: 1.5.7152.31018
     For more information, please see http://wiki.ros.org/sw_urdf_exporter -->
<robot name="diana_v2">
  <material name="Blue">
    <color rgba="0.0 0.0 0.8 1.0"/>
  </material>
  <material name="Green">
    <color rgba="0.0 0.8 0.0 1.0"/>
  </material>
  <material name="Grey">
    <color rgba="0.2 0.2 0.2 1.0"/>
  </material>
  <material name="LightGrey">
    <color rgba="0.6 0.6 0.6 1.0"/>
  </material>
  <material name="Red">
    <color rgba="0.8 0.0 0.0 1.0"/>
  </material>
  <material name="White">
    <color rgba="1.0 1.0 1.0 1.0"/>
  </material>
  <material name="white">
    <color rgba="1.0 1.0 1.0 1.0"/>
  </material>
  <link name="base">
    <inertial>
      <origin rpy="0 0 0" xyz="0.00153097191906452 0.00152031034664837 0.0524230280849149"/>
      <mass value="1.33110743457779"/>
      <inertia ixx="0.00695879790529406" ixy="9.99328685258342E-05" ixz="7.99577031212481E-05" iyy="0.00695365531716522" iyz="7.90796997368543E-05" izz="0.00729823323321907"/>
    </inertial>
    <visual>
      <origin rpy="0 0 0" xyz="0 0 0"/>
      <geometry>
        <mesh filename="/home/k/Desktop/Projects/isaacgymenvs_diana7/Arnie/arnie/models/diana_v2/meshes/visual/base.obj"/>
      </geometry>
      <material name="">
        <color rgba="0.796078431372549 0.823529411764706 0.937254901960784 1"/>
      </material>
    </visual>
    <collision>
      <origin rpy="0 0 0" xyz="0 0 0"/>
      <geometry>
        <mesh filename="/home/k/Desktop/Projects/isaacgymenvs_diana7/Arnie/arnie/models/diana_v2/meshes/collision/base.stl"/>
      </geometry>
    </collision>
  </link>
  <link name="link_1">
    <inertial>
      <origin rpy="0 0 0" xyz="5.5234067920554E-05  -0.0254878204920178 0.0355441421264809"/>
      <mass value="1.09025546409174"/>
      <inertia ixx="0.00585031196428369" ixy="1.4630349447555E-07" ixz="1.35351687162397E-06" iyy="0.00645496952227061" iyz="-0.00104800484741808" izz="0.00459531291521244"/>
    </inertial>
    <visual>
      <origin rpy="3.1415926531795866 0 0" xyz="0 0 0"/>
      <geometry>
        <mesh filename="/home/k/Desktop/Projects/isaacgymenvs_diana7/Arnie/arnie/models/diana_v2/meshes/visual/link_1.obj"/>
      </geometry>
      <material name="">
        <color rgba="0.796078431372549 0.823529411764706 0.937254901960784 1"/>
      </material>
    </visual>
    <collision>
      <origin rpy="3.1415926531795866 0 0" xyz="0 0 0"/>
      <geometry>
        <mesh filename="/home/k/Desktop/Projects/isaacgymenvs_diana7/Arnie/arnie/models/diana_v2/meshes/collision/link_1.stl"/>
      </geometry>
    </collision>
  </link>
  <joint name="joint_1" type="revolute">
    <origin rpy="-3.1415926535795866 0.0 -0.0" xyz="0.0 -2.9150689157e-12 0.2856"/>
    <parent link="base"/>
    <child link="link_1"/>
    <axis xyz="0 0 1"/>
    <limit effort="235" lower="-3.12" upper="3.12" velocity="2.618"/>
  </joint>
  <link name="link_2">
    <inertial>
      <origin rpy="0 0 0" xyz="-3.62724763868157E-06 -0.0292741005087307 -0.041280769252073"/>
      <mass value="1.09515454908799"/>
      <inertia ixx="0.00575817488413533" ixy="4.92454490330888E-07" ixz="-5.75758988171004E-07" iyy="0.00452592941277235" iyz="0.00135206824645357" izz="0.0058904584276842"/>
    </inertial>
    <visual>
      <origin rpy="0 0 0" xyz="0 0 0"/>
      <geometry>
        <mesh filename="/home/k/Desktop/Projects/isaacgymenvs_diana7/Arnie/arnie/models/diana_v2/meshes/visual/link_2.obj"/>
      </geometry>
      <material name="">
        <color rgba="0.980392156862745 0.980392156862745 0.470588235294118 1"/>
      </material>
    </visual>
    <collision>
      <origin rpy="0 0 0" xyz="0 0 0"/>
      <geometry>
        <mesh filename="/home/k/Desktop/Projects/isaacgymenvs_diana7/Arnie/arnie/models/diana_v2/meshes/collision/link_2.stl"/>
      </geometry>
    </collision>
  </link>
  <joint name="joint_2" type="revolute">
    <origin rpy="1.57079632679 -0.0 0.0" xyz="0.0 -0.0 0.0"/>
    <parent link="link_1"/>
    <child link="link_2"/>
    <axis xyz="0 0 1"/>
    <limit effort="235" lower="-1.57" upper="1.57" velocity="2.618"/>
  </joint>
  <link name="link_3">
    <inertial>
      <origin rpy="0 3.1415926531795866 3.1415926531795866" xyz="0.0114318213510691 -0.0101707598694861 0.15131695375217"/>
      <mass value="2.01686690128149"/>
      <inertia ixx="0.0362470020041464" ixy="-0.00099203786071914" ixz="-0.00494440140493448" iyy="0.0374857206758098" iyz="-0.00313859974095155" izz="0.00905850119342719"/>
    </inertial>
    <visual>
      <origin rpy="3.1415926531795866 0 0" xyz="0 0 0"/>
      <geometry>
        <mesh filename="/home/k/Desktop/Projects/isaacgymenvs_diana7/Arnie/arnie/models/diana_v2/meshes/visual/link_3.obj"/>
      </geometry>
      <material name="">
        <color rgba="0.898039215686275 0.917647058823529 0.929411764705882 1"/>
      </material>
    </visual>
    <collision>
      <origin rpy="3.1415926531795866 0 0" xyz="0 0 0"/>
      <geometry>
        <mesh filename="/home/k/Desktop/Projects/isaacgymenvs_diana7/Arnie/arnie/models/diana_v2/meshes/collision/link_3.stl"/>
      </geometry>
    </collision>
  </link>
  <joint name="joint_3" type="revolute">
    <origin rpy="-1.57079632679 0.0 0.0" xyz="0.0 -0.4586 -2.24557565126e-12"/>
    <parent link="link_2"/>
    <child link="link_3"/>
    <axis xyz="0 0 1"/>
    <limit effort="111" lower="-3.12" upper="3.12" velocity="3.1416"/>
  </joint>
  <link name="link_4">
    <inertial>
      <origin rpy="0 0 0" xyz="-0.0240716370537192 -0.0235631728011761 -0.0366858174253844"/>
      <mass value="0.849743349506889"/>
      <inertia ixx="0.00313444335639628" ixy="-0.000681243351041131" ixz="0.000725380047812207" iyy="0.00333717642442852" iyz="0.000771057559109157" izz="0.0034847726349841"/>
    </inertial>
    <visual>
      <origin rpy="0 0 0" xyz="0 0 0"/>
      <geometry>
        <mesh filename="/home/k/Desktop/Projects/isaacgymenvs_diana7/Arnie/arnie/models/diana_v2/meshes/visual/link_4.obj"/>
      </geometry>
      <material name="">
        <color rgba="0.898039215686275 0.917647058823529 0.929411764705882 1"/>
      </material>
    </visual>
    <collision>
      <origin rpy="0 0 0" xyz="0 0 0"/>
      <geometry>
        <mesh filename="/home/k/Desktop/Projects/isaacgymenvs_diana7/Arnie/arnie/models/diana_v2/meshes/collision/link_4.stl"/>
      </geometry>
    </collision>
  </link>
  <joint name="joint_4" type="revolute">
    <origin rpy="1.57079632679 -0.0 0.0" xyz="0.065 -0.0 0.0"/>
    <parent link="link_3"/>
    <child link="link_4"/>
    <axis xyz="0 0 1"/>
    <limit effort="111" lower="0" upper="3.05" velocity="3.1416"/>
  </joint>
  <link name="link_5">
    <inertial>
      <origin rpy="0 3.1415926531795866 3.1415926531795866" xyz="-0.00867148011164554 0.0383499684802812 0.188626"/>
      <mass value="1.20580396965245"/>
      <inertia ixx="0.0218436427570802" ixy="-0.000309747330693722" ixz="0.00089039094846826" iyy="0.0205896836785318" iyz="0.00493573923914426" izz="0.00372270106038425"/>
    </inertial>
    <visual>
      <origin rpy="3.1415926531795866 0 0" xyz="0 0 -0.02162"/>
      <geometry>
        <mesh filename="/home/k/Desktop/Projects/isaacgymenvs_diana7/Arnie/arnie/models/diana_v2/meshes/visual/link_5.obj"/>
      </geometry>
      <material name="">
        <color rgba="0.898039215686275 0.917647058823529 0.929411764705882 1"/>
      </material>
    </visual>
    <collision>
      <origin rpy="3.1415926531795866 0 0" xyz="0 0 -0.02162"/>
      <geometry>
        <mesh filename="/home/k/Desktop/Projects/isaacgymenvs_diana7/Arnie/arnie/models/diana_v2/meshes/collision/link_5.stl"/>
      </geometry>
    </collision>
  </link>
  <joint name="joint_5" type="revolute">
    <origin rpy="-1.57079632679 0.0 0.0" xyz="-0.0528 -0.4554 -2.22990656691e-12"/>
    <parent link="link_4"/>
    <child link="link_5"/>
    <axis xyz="0 0 1"/>
    <limit effort="54" lower="-3.12" upper="3.12" velocity="2.618"/>
  </joint>
  <link name="link_6">
    <inertial>
      <origin rpy="0 3.1415926531795866 3.1415926531795866" xyz="0.045897226241036 0.00848579821002571 -0.0078257811617596"/>
      <mass value="0.847157564562275"/>
      <inertia ixx="0.00286926864109097" ixy="-0.000341664135091818" ixz="-0.000318082297486923" iyy="0.0043294660443987" iyz="-5.82962380662208E-05" izz="0.00437292566725527"/>
    </inertial>
    <visual>
      <origin rpy="3.1415926531795866 0 3.14159265359" xyz="0 0 0"/>
      <geometry>
        <mesh filename="/home/k/Desktop/Projects/isaacgymenvs_diana7/Arnie/arnie/models/diana_v2/meshes/visual/link_6.obj"/>
      </geometry>
      <material name="">
        <color rgba="0.980392156862745 0.980392156862745 0.470588235294118 1"/>
      </material>
    </visual>
    <collision>
      <origin rpy="3.1415926531795866 0 3.14159265359" xyz="0 0 0"/>
      <geometry>
        <mesh filename="/home/k/Desktop/Projects/isaacgymenvs_diana7/Arnie/arnie/models/diana_v2/meshes/collision/link_6.stl"/>
      </geometry>
    </collision>
  </link>
  <joint name="joint_6" type="revolute">
    <origin rpy="1.57079632679 -1.0206823934513925e-11 -3.141592653589793" xyz="-0.0122 0.0 0.0"/>
    <parent link="link_5"/>
    <child link="link_6"/>
    <axis xyz="0 0 1"/>
    <limit effort="54" lower="-3.12" upper="0.52" velocity="2.618"/>
  </joint>
  <link name="link_7">
    <inertial>
      <origin rpy="0 0 0" xyz="0.00117005127509708 5.03191940906655E-06 0.0151381784822231"/>
      <mass value="0.233956150459573"/>
      <inertia ixx="0.000142027360977168" ixy="1.76426389345981E-08" ixz="2.14635741626268E-07" iyy="0.000134421724783865" iyz="-1.29988689037464E-09" izz="0.000240242798572463"/>
    </inertial>
    <visual>
      <origin rpy="0 0 0" xyz="0 0 0"/>
      <geometry>
        <mesh filename="/home/k/Desktop/Projects/isaacgymenvs_diana7/Arnie/arnie/models/diana_v2/meshes/visual/link_7.obj"/>
      </geometry>
      <material name="">
        <color rgba="0.898039215686275 0.917647058823529 0.929411764705882 1"/>
      </material>
    </visual>
    <collision>
      <origin rpy="0 0 0" xyz="0 0 0"/>
      <geometry>
        <mesh filename="/home/k/Desktop/Projects/isaacgymenvs_diana7/Arnie/arnie/models/diana_v2/meshes/collision/link_7.stl"/>
      </geometry>
    </collision>
  </link>
  <joint name="joint_7" type="revolute">
    <origin rpy="-1.57079632679 0.0 0.0" xyz="0.087 -0.1169 -5.72411237751e-13"/>
    <parent link="link_6"/>
    <child link="link_7"/>
    <axis xyz="0 0 1"/>
    <limit effort="54" lower="-3.12" upper="3.12" velocity="3.1416"/>
  </joint>
  <!-- Nat: here is the original diana_2.urdf file's content, the content below adds the hand to the code -->
  <link name="link_7_fake">
  </link>
  <joint name="link_7_to_link_7_fake" type="fixed">
    <parent link="link_7" />
    <child link="link_7_fake" />
    <origin rpy="3.1415926 0 0" xyz="0 0 0" />
  </joint>
  <joint name="arm_to_hithand_fix_joint" type="fixed">
    <parent link="link_7_fake"/>
    <child link="base_link_hithand"/>
    <!-- <origin rpy="-1.57 0 0" xyz="0 0 -0.05"/> -->
      <origin rpy="0 0 0" xyz="0 0 0.0"/>
  </joint>
  <!-- ++++ Define all the links and joints ++++ -->
  <!-- Starting from the base -->
  <link name="base_link_hithand">
    <inertial>
      <origin rpy="0 0 0" xyz="0.0 0.0 0.0"/>
      <mass value="1.1485"/>
      <inertia ixx="2.2458e-3" ixy="-2.7421e-4" ixz="1.6e-5" iyy="2.2203e-3" iyz="-6.37e-5" izz="1.9003e-3"/>
    </inertial>
    <visual>
      <origin rpy="-1.57 0 0" xyz="0 0 0"/>
      <geometry>
        <mesh filename="/home/k/Desktop/Projects/isaacgymenvs_diana7/Arnie/arnie/models/diana_v2_with_hithand/meshes/visual/palm/hit-hand-2-palm-right-diana-rot.dae"/>
      </geometry>
      <material name="white"/>
    </visual>
    <collision>
      <origin rpy="-1.57 0 0" xyz="0 0 0"/>
      <geometry>
        <mesh filename="/home/k/Desktop/Projects/isaacgymenvs_diana7/Arnie/arnie/models/diana_v2_with_hithand/meshes/collision/palm/hit-hand-2-palm-right.stl"/>
      </geometry>
      <disable>true</disable>
    </collision>
  </link>
  <!-- Add a virtual palm link to get the transform of this point via TF for grasping (we align this frame with
        a normal of a point from an object point cloud.) -->
  <joint name="hithand_palm_joint" type="fixed">
    <parent link="base_link_hithand"/>
    <child link="palm_link_hithand"/>
    <origin rpy="-0.15 -1.3 0" xyz="0.02 0 0.06"/>
  </joint>
  <link name="palm_link_hithand"/>
  <!-- #########################FINGER######################## -->
  <!-- END of finger macro -->
  <!-- +++++ Finger base joint 0 ++++++ -->
  <joint name="Right_Thumb_0" type="revolute">
    <!-- joint origin in parent link frame -->
    <origin rpy="0.225810 -1.083656 0.411355" xyz="0.06217593 0.044372912 0.078734808"/>
    <parent link="base_link_hithand"/>
    <child link="Right_Thumb_Basecover"/>
    <axis xyz="0 0 1"/>
    <limit effort="15" lower="-0.261799" upper="0.261799" velocity="3.14"/>
    <dynamics damping="0.5" friction="0"/>
  </joint>
  <link name="Right_Thumb_Basecover">
    <inertial>
      <origin rpy="0 0 0" xyz="0.02749 0 0"/>
      <mass value="0.0176"/>
      <inertia ixx="1.3450e-6" ixy="0.0" ixz="-1.8183e-7" iyy="1.9874e-6" iyz="0.0" izz="1.0419e-6"/>
    </inertial>
    <visual>
      <origin rpy="0 0 0" xyz="0 0 0"/>
      <geometry>
        <mesh filename="/home/k/Desktop/Projects/isaacgymenvs_diana7/Arnie/arnie/models/diana_v2_with_hithand/meshes/visual/finger/hit-hand-2-finger-basecover.dae"/>
      </geometry>
      <material name="white"/>
    </visual>
    <collision>
      <origin rpy="0 0 0" xyz="0 0 0"/>
      <geometry name="hithand_Thumb_base_cover">
        <cylinder length="0.001" radius="0.001"/>
      </geometry>
    </collision>
  </link>
  <!-- +++++ Finger joint 1, Link: Phalanx proximalis ++++++ -->
  <joint name="Right_Thumb_1" type="revolute">
    <origin rpy="1.5708 0 0" xyz="0 0 0 "/>
    <parent link="Right_Thumb_Basecover"/>
    <child link="Right_Thumb_Phaprox"/>
    <axis xyz="0 0 1"/>
    <limit effort="1.15" lower="0.0" upper="1.48353" velocity="3.14"/>
    <!-- Effort limit based on max fingertip force of 10N. Finger tip is approx 11.5cm away from this joint.-->
    <dynamics damping="0.5" friction="0"/>
  </joint>
  <link name="Right_Thumb_Phaprox">
    <inertial>
      <origin rpy="0 0 0" xyz="0.03076 0.00297 0"/>
      <mass value="0.0232"/>
      <inertia ixx="2.5326e-6" ixy="-9.2551e-7" ixz="-4.0954e-8" iyy="6.9625e-6" iyz="-9.38e-9" izz="7.9108e-6"/>
    </inertial>
    <visual>
      <origin rpy="0 0 0" xyz="0 0 0"/>
      <geometry>
        <mesh filename="/home/k/Desktop/Projects/isaacgymenvs_diana7/Arnie/arnie/models/diana_v2_with_hithand/meshes/visual/finger/hit-hand-2-finger-phaprox-diana-rot.dae"/>
      </geometry>
      <material name="white"/>
    </visual>
    <collision>
      <origin rpy="0 0 0" xyz="0 0 0"/>
      <geometry>
        <mesh filename="/home/k/Desktop/Projects/isaacgymenvs_diana7/Arnie/arnie/models/diana_v2_with_hithand/meshes/collision/finger/hit-hand-2-finger-phaprox.stl"/>
      </geometry>
    </collision>
  </link>
  <!-- +++++ Finger joint 2 Phalanx medialis ++++++ -->
  <joint name="Right_Thumb_2" type="revolute">
    <origin rpy="0 0 0" xyz="0.055 0 0"/>
    <parent link="Right_Thumb_Phaprox"/>
    <child link="Right_Thumb_Phamed"/>
    <axis xyz="0 0 1"/>
    <limit effort="0.6" lower="0.0" upper="1.13446" velocity="3.14"/>
    <!-- Effort limit based on max fingertip force of 10N. Finger tip is approx 6cm away from this joint.-->
    <dynamics damping="0.5" friction="0"/>
  </joint>
  <link name="Right_Thumb_Phamed">
    <inertial>
      <origin rpy="0 0 0" xyz="0.0097 -0.00036 0"/>
      <mass value="0.0158"/>
      <inertia ixx="1.1852e-6" ixy="-2.8845e-8" ixz="-6.1323e-9" iyy="2.4460e-6" iyz="2.4541e-9" izz="2.6537e-6"/>
    </inertial>
    <visual>
      <origin rpy="0 0 0" xyz="0 0 0"/>
      <geometry>
        <mesh filename="/home/k/Desktop/Projects/isaacgymenvs_diana7/Arnie/arnie/models/diana_v2_with_hithand/meshes/visual/finger/hit-hand-2-finger-phamed-diana-rot.dae"/>
      </geometry>
      <material name="white"/>
    </visual>
    <collision>
      <origin rpy="0 0 0" xyz="0 0 0"/>
      <geometry>
        <mesh filename="/home/k/Desktop/Projects/isaacgymenvs_diana7/Arnie/arnie/models/diana_v2_with_hithand/meshes/collision/finger/hit-hand-2-finger-phamed.stl"/>
      </geometry>
    </collision>
  </link>
  <!-- +++++ Finger joint 3 Phalanx distalis ++++++ -->
  <joint name="Right_Thumb_3" type="revolute">
    <origin rpy="0 0 -1.570796" xyz="0.025 0 0"/>
    <parent link="Right_Thumb_Phamed"/>
    <child link="Right_Thumb_Phadist"/>
    <axis xyz="0 0 1"/>
    <limit effort="0.35" lower="0.0" upper="1.13446" velocity="3.14"/>
    <!-- Effort limit based on max fingertip force of 10N. Finger tip is approx 3.5cm away from this joint.-->
    <dynamics damping="0.5" friction="0"/>
  </joint>
  <link name="Right_Thumb_Phadist">
    <inertial>
      <origin rpy="0 0 0" xyz="0.00072 0.00717 0.0"/>
      <mass value="0.0137"/>
      <inertia ixx="1.5519e-6" ixy="-2.037e-9" ixz="0.0" iyy="8.2972e-7" iyz="3.77e-9" izz="1.5788e-6"/>
    </inertial>
    <visual>
      <origin rpy="0 0 0" xyz="0 0 0"/>
      <geometry>
        <mesh filename="/home/k/Desktop/Projects/isaacgymenvs_diana7/Arnie/arnie/models/diana_v2_with_hithand/meshes/visual/finger/hit-hand-2-finger-phadist-diana-rot.dae"/>
      </geometry>
      <material name="white"/>
    </visual>
    <collision>
      <origin rpy="0 0 0" xyz="0 0 0"/>
      <geometry>
        <mesh filename="/home/k/Desktop/Projects/isaacgymenvs_diana7/Arnie/arnie/models/diana_v2_with_hithand/meshes/collision/finger/hit-hand-2-finger-phadist.stl"/>
      </geometry>
    </collision>
  </link>
  <!-- +++++ Finger base joint 0 ++++++ -->
  <joint name="Right_Index_0" type="revolute">
    <!-- joint origin in parent link frame -->
    <origin rpy="3.054326 -1.570796 0.000000" xyz="-0.002529881 0.03680013 0.107783545"/>
    <parent link="base_link_hithand"/>
    <child link="Right_Index_Basecover"/>
    <axis xyz="0 0 1"/>
    <limit effort="15" lower="-0.261799" upper="0.261799" velocity="3.14"/>
    <dynamics damping="0.5" friction="0"/>
  </joint>
  <link name="Right_Index_Basecover">
    <inertial>
      <origin rpy="0 0 0" xyz="0.02749 0 0"/>
      <mass value="0.0176"/>
      <inertia ixx="1.3450e-6" ixy="0.0" ixz="-1.8183e-7" iyy="1.9874e-6" iyz="0.0" izz="1.0419e-6"/>
    </inertial>
    <visual>
      <origin rpy="0 0 0" xyz="0 0 0"/>
      <geometry>
        <mesh filename="/home/k/Desktop/Projects/isaacgymenvs_diana7/Arnie/arnie/models/diana_v2_with_hithand/meshes/visual/finger/hit-hand-2-finger-basecover.dae"/>
      </geometry>
      <material name="white"/>
    </visual>
    <collision>
      <origin rpy="0 0 0" xyz="0 0 0"/>
      <geometry name="hithand_Index_base_cover">
        <cylinder length="0.001" radius="0.001"/>
      </geometry>
    </collision>
  </link>
  <!-- +++++ Finger joint 1, Link: Phalanx proximalis ++++++ -->
  <joint name="Right_Index_1" type="revolute">
    <origin rpy="1.5708 0 0" xyz="0 0 0 "/>
    <parent link="Right_Index_Basecover"/>
    <child link="Right_Index_Phaprox"/>
    <axis xyz="0 0 1"/>
    <limit effort="1.15" lower="0.0" upper="1.48353" velocity="3.14"/>
    <!-- Effort limit based on max fingertip force of 10N. Finger tip is approx 11.5cm away from this joint.-->
    <dynamics damping="0.5" friction="0"/>
  </joint>
  <link name="Right_Index_Phaprox">
    <inertial>
      <origin rpy="0 0 0" xyz="0.03076 0.00297 0"/>
      <mass value="0.0232"/>
      <inertia ixx="2.5326e-6" ixy="-9.2551e-7" ixz="-4.0954e-8" iyy="6.9625e-6" iyz="-9.38e-9" izz="7.9108e-6"/>
    </inertial>
    <visual>
      <origin rpy="0 0 0" xyz="0 0 0"/>
      <geometry>
        <mesh filename="/home/k/Desktop/Projects/isaacgymenvs_diana7/Arnie/arnie/models/diana_v2_with_hithand/meshes/visual/finger/hit-hand-2-finger-phaprox-diana-rot.dae"/>
      </geometry>
      <material name="white"/>
    </visual>
    <collision>
      <origin rpy="0 0 0" xyz="0 0 0"/>
      <geometry>
        <mesh filename="/home/k/Desktop/Projects/isaacgymenvs_diana7/Arnie/arnie/models/diana_v2_with_hithand/meshes/collision/finger/hit-hand-2-finger-phaprox.stl"/>
      </geometry>
    </collision>
  </link>
  <!-- +++++ Finger joint 2 Phalanx medialis ++++++ -->
  <joint name="Right_Index_2" type="revolute">
    <origin rpy="0 0 0" xyz="0.055 0 0"/>
    <parent link="Right_Index_Phaprox"/>
    <child link="Right_Index_Phamed"/>
    <axis xyz="0 0 1"/>
    <limit effort="0.6" lower="0.0" upper="1.13446" velocity="3.14"/>
    <!-- Effort limit based on max fingertip force of 10N. Finger tip is approx 6cm away from this joint.-->
    <dynamics damping="0.5" friction="0"/>
  </joint>
  <link name="Right_Index_Phamed">
    <inertial>
      <origin rpy="0 0 0" xyz="0.0097 -0.00036 0"/>
      <mass value="0.0158"/>
      <inertia ixx="1.1852e-6" ixy="-2.8845e-8" ixz="-6.1323e-9" iyy="2.4460e-6" iyz="2.4541e-9" izz="2.6537e-6"/>
    </inertial>
    <visual>
      <origin rpy="0 0 0" xyz="0 0 0"/>
      <geometry>
        <mesh filename="/home/k/Desktop/Projects/isaacgymenvs_diana7/Arnie/arnie/models/diana_v2_with_hithand/meshes/visual/finger/hit-hand-2-finger-phamed-diana-rot.dae"/>
      </geometry>
      <material name="white"/>
    </visual>
    <collision>
      <origin rpy="0 0 0" xyz="0 0 0"/>
      <geometry>
        <mesh filename="/home/k/Desktop/Projects/isaacgymenvs_diana7/Arnie/arnie/models/diana_v2_with_hithand/meshes/collision/finger/hit-hand-2-finger-phamed.stl"/>
      </geometry>
    </collision>
  </link>
  <!-- +++++ Finger joint 3 Phalanx distalis ++++++ -->
  <joint name="Right_Index_3" type="revolute">
    <origin rpy="0 0 -1.570796" xyz="0.025 0 0"/>
    <parent link="Right_Index_Phamed"/>
    <child link="Right_Index_Phadist"/>
    <axis xyz="0 0 1"/>
    <limit effort="0.35" lower="0.0" upper="1.13446" velocity="3.14"/>
    <!-- Effort limit based on max fingertip force of 10N. Finger tip is approx 3.5cm away from this joint.-->
    <dynamics damping="0.5" friction="0"/>
  </joint>
  <link name="Right_Index_Phadist">
    <inertial>
      <origin rpy="0 0 0" xyz="0.00072 0.00717 0.0"/>
      <mass value="0.0137"/>
      <inertia ixx="1.5519e-6" ixy="-2.037e-9" ixz="0.0" iyy="8.2972e-7" iyz="3.77e-9" izz="1.5788e-6"/>
    </inertial>
    <visual>
      <origin rpy="0 0 0" xyz="0 0 0"/>
      <geometry>
        <mesh filename="/home/k/Desktop/Projects/isaacgymenvs_diana7/Arnie/arnie/models/diana_v2_with_hithand/meshes/visual/finger/hit-hand-2-finger-phadist-diana-rot.dae"/>
      </geometry>
      <material name="white"/>
    </visual>
    <collision>
      <origin rpy="0 0 0" xyz="0 0 0"/>
      <geometry>
        <mesh filename="/home/k/Desktop/Projects/isaacgymenvs_diana7/Arnie/arnie/models/diana_v2_with_hithand/meshes/collision/finger/hit-hand-2-finger-phadist.stl"/>
      </geometry>
    </collision>
  </link>
  <!-- +++++ Finger base joint 0 ++++++ -->
  <joint name="Right_Middle_0" type="revolute">
    <!-- joint origin in parent link frame -->
    <origin rpy="-3.141593 -1.570796 0.000000" xyz="-0.0037 0.01  0.117783545"/>
    <parent link="base_link_hithand"/>
    <child link="Right_Middle_Basecover"/>
    <axis xyz="0 0 1"/>
    <limit effort="15" lower="-0.261799" upper="0.261799" velocity="3.14"/>
    <dynamics damping="0.5" friction="0"/>
  </joint>
  <link name="Right_Middle_Basecover">
    <inertial>
      <origin rpy="0 0 0" xyz="0.02749 0 0"/>
      <mass value="0.0176"/>
      <inertia ixx="1.3450e-6" ixy="0.0" ixz="-1.8183e-7" iyy="1.9874e-6" iyz="0.0" izz="1.0419e-6"/>
    </inertial>
    <visual>
      <origin rpy="0 0 0" xyz="0 0 0"/>
      <geometry>
        <mesh filename="/home/k/Desktop/Projects/isaacgymenvs_diana7/Arnie/arnie/models/diana_v2_with_hithand/meshes/visual/finger/hit-hand-2-finger-basecover.dae"/>
      </geometry>
      <material name="white"/>
    </visual>
    <collision>
      <origin rpy="0 0 0" xyz="0 0 0"/>
      <geometry name="hithand_Middle_base_cover">
        <cylinder length="0.001" radius="0.001"/>
      </geometry>
    </collision>
  </link>
  <!-- +++++ Finger joint 1, Link: Phalanx proximalis ++++++ -->
  <joint name="Right_Middle_1" type="revolute">
    <origin rpy="1.5708 0 0" xyz="0 0 0 "/>
    <parent link="Right_Middle_Basecover"/>
    <child link="Right_Middle_Phaprox"/>
    <axis xyz="0 0 1"/>
    <limit effort="1.15" lower="0.0" upper="1.48353" velocity="3.14"/>
    <!-- Effort limit based on max fingertip force of 10N. Finger tip is approx 11.5cm away from this joint.-->
    <dynamics damping="0.5" friction="0"/>
  </joint>
  <link name="Right_Middle_Phaprox">
    <inertial>
      <origin rpy="0 0 0" xyz="0.03076 0.00297 0"/>
      <mass value="0.0232"/>
      <inertia ixx="2.5326e-6" ixy="-9.2551e-7" ixz="-4.0954e-8" iyy="6.9625e-6" iyz="-9.38e-9" izz="7.9108e-6"/>
    </inertial>
    <visual>
      <origin rpy="0 0 0" xyz="0 0 0"/>
      <geometry>
        <mesh filename="/home/k/Desktop/Projects/isaacgymenvs_diana7/Arnie/arnie/models/diana_v2_with_hithand/meshes/visual/finger/hit-hand-2-finger-phaprox-diana-rot.dae"/>
      </geometry>
      <material name="white"/>
    </visual>
    <collision>
      <origin rpy="0 0 0" xyz="0 0 0"/>
      <geometry>
        <mesh filename="/home/k/Desktop/Projects/isaacgymenvs_diana7/Arnie/arnie/models/diana_v2_with_hithand/meshes/collision/finger/hit-hand-2-finger-phaprox.stl"/>
      </geometry>
    </collision>
  </link>
  <!-- +++++ Finger joint 2 Phalanx medialis ++++++ -->
  <joint name="Right_Middle_2" type="revolute">
    <origin rpy="0 0 0" xyz="0.055 0 0"/>
    <parent link="Right_Middle_Phaprox"/>
    <child link="Right_Middle_Phamed"/>
    <axis xyz="0 0 1"/>
    <limit effort="0.6" lower="0.0" upper="1.13446" velocity="3.14"/>
    <!-- Effort limit based on max fingertip force of 10N. Finger tip is approx 6cm away from this joint.-->
    <dynamics damping="0.5" friction="0"/>
  </joint>
  <link name="Right_Middle_Phamed">
    <inertial>
      <origin rpy="0 0 0" xyz="0.0097 -0.00036 0"/>
      <mass value="0.0158"/>
      <inertia ixx="1.1852e-6" ixy="-2.8845e-8" ixz="-6.1323e-9" iyy="2.4460e-6" iyz="2.4541e-9" izz="2.6537e-6"/>
    </inertial>
    <visual>
      <origin rpy="0 0 0" xyz="0 0 0"/>
      <geometry>
        <mesh filename="/home/k/Desktop/Projects/isaacgymenvs_diana7/Arnie/arnie/models/diana_v2_with_hithand/meshes/visual/finger/hit-hand-2-finger-phamed-diana-rot.dae"/>
      </geometry>
      <material name="white"/>
    </visual>
    <collision>
      <origin rpy="0 0 0" xyz="0 0 0"/>
      <geometry>
        <mesh filename="/home/k/Desktop/Projects/isaacgymenvs_diana7/Arnie/arnie/models/diana_v2_with_hithand/meshes/collision/finger/hit-hand-2-finger-phamed.stl"/>
      </geometry>
    </collision>
  </link>
  <!-- +++++ Finger joint 3 Phalanx distalis ++++++ -->
  <joint name="Right_Middle_3" type="revolute">
    <origin rpy="0 0 -1.570796" xyz="0.025 0 0"/>
    <parent link="Right_Middle_Phamed"/>
    <child link="Right_Middle_Phadist"/>
    <axis xyz="0 0 1"/>
    <limit effort="0.35" lower="0.0" upper="1.13446" velocity="3.14"/>
    <!-- Effort limit based on max fingertip force of 10N. Finger tip is approx 3.5cm away from this joint.-->
    <dynamics damping="0.5" friction="0"/>
  </joint>
  <link name="Right_Middle_Phadist">
    <inertial>
      <origin rpy="0 0 0" xyz="0.00072 0.00717 0.0"/>
      <mass value="0.0137"/>
      <inertia ixx="1.5519e-6" ixy="-2.037e-9" ixz="0.0" iyy="8.2972e-7" iyz="3.77e-9" izz="1.5788e-6"/>
    </inertial>
    <visual>
      <origin rpy="0 0 0" xyz="0 0 0"/>
      <geometry>
        <mesh filename="/home/k/Desktop/Projects/isaacgymenvs_diana7/Arnie/arnie/models/diana_v2_with_hithand/meshes/visual/finger/hit-hand-2-finger-phadist-diana-rot.dae"/>
      </geometry>
      <material name="white"/>
    </visual>
    <collision>
      <origin rpy="0 0 0" xyz="0 0 0"/>
      <geometry>
        <mesh filename="/home/k/Desktop/Projects/isaacgymenvs_diana7/Arnie/arnie/models/diana_v2_with_hithand/meshes/collision/finger/hit-hand-2-finger-phadist.stl"/>
      </geometry>
    </collision>
  </link>
  <!-- +++++ Finger base joint 0 ++++++ -->
  <joint name="Right_Ring_0" type="revolute">
    <!-- joint origin in parent link frame -->
    <origin rpy="-3.054326 -1.570796 0.000000" xyz="0 -0.01680013 0.11258354"/>
    <parent link="base_link_hithand"/>
    <child link="Right_Ring_Basecover"/>
    <axis xyz="0 0 1"/>
    <limit effort="15" lower="-0.261799" upper="0.261799" velocity="3.14"/>
    <dynamics damping="0.5" friction="0"/>
  </joint>
  <link name="Right_Ring_Basecover">
    <inertial>
      <origin rpy="0 0 0" xyz="0.02749 0 0"/>
      <mass value="0.0176"/>
      <inertia ixx="1.3450e-6" ixy="0.0" ixz="-1.8183e-7" iyy="1.9874e-6" iyz="0.0" izz="1.0419e-6"/>
    </inertial>
    <visual>
      <origin rpy="0 0 0" xyz="0 0 0"/>
      <geometry>
        <mesh filename="/home/k/Desktop/Projects/isaacgymenvs_diana7/Arnie/arnie/models/diana_v2_with_hithand/meshes/visual/finger/hit-hand-2-finger-basecover.dae"/>
      </geometry>
      <material name="white"/>
    </visual>
    <collision>
      <origin rpy="0 0 0" xyz="0 0 0"/>
      <geometry name="hithand_Ring_base_cover">
        <cylinder length="0.001" radius="0.001"/>
      </geometry>
    </collision>
  </link>
  <!-- +++++ Finger joint 1, Link: Phalanx proximalis ++++++ -->
  <joint name="Right_Ring_1" type="revolute">
    <origin rpy="1.5708 0 0" xyz="0 0 0 "/>
    <parent link="Right_Ring_Basecover"/>
    <child link="Right_Ring_Phaprox"/>
    <axis xyz="0 0 1"/>
    <limit effort="1.15" lower="0.0" upper="1.48353" velocity="3.14"/>
    <!-- Effort limit based on max fingertip force of 10N. Finger tip is approx 11.5cm away from this joint.-->
    <dynamics damping="0.5" friction="0"/>
  </joint>
  <link name="Right_Ring_Phaprox">
    <inertial>
      <origin rpy="0 0 0" xyz="0.03076 0.00297 0"/>
      <mass value="0.0232"/>
      <inertia ixx="2.5326e-6" ixy="-9.2551e-7" ixz="-4.0954e-8" iyy="6.9625e-6" iyz="-9.38e-9" izz="7.9108e-6"/>
    </inertial>
    <visual>
      <origin rpy="0 0 0" xyz="0 0 0"/>
      <geometry>
        <mesh filename="/home/k/Desktop/Projects/isaacgymenvs_diana7/Arnie/arnie/models/diana_v2_with_hithand/meshes/visual/finger/hit-hand-2-finger-phaprox-diana-rot.dae"/>
      </geometry>
      <material name="white"/>
    </visual>
    <collision>
      <origin rpy="0 0 0" xyz="0 0 0"/>
      <geometry>
        <mesh filename="/home/k/Desktop/Projects/isaacgymenvs_diana7/Arnie/arnie/models/diana_v2_with_hithand/meshes/collision/finger/hit-hand-2-finger-phaprox.stl"/>
      </geometry>
    </collision>
  </link>
  <!-- +++++ Finger joint 2 Phalanx medialis ++++++ -->
  <joint name="Right_Ring_2" type="revolute">
    <origin rpy="0 0 0" xyz="0.055 0 0"/>
    <parent link="Right_Ring_Phaprox"/>
    <child link="Right_Ring_Phamed"/>
    <axis xyz="0 0 1"/>
    <limit effort="0.6" lower="0.0" upper="1.13446" velocity="3.14"/>
    <!-- Effort limit based on max fingertip force of 10N. Finger tip is approx 6cm away from this joint.-->
    <dynamics damping="0.5" friction="0"/>
  </joint>
  <link name="Right_Ring_Phamed">
    <inertial>
      <origin rpy="0 0 0" xyz="0.0097 -0.00036 0"/>
      <mass value="0.0158"/>
      <inertia ixx="1.1852e-6" ixy="-2.8845e-8" ixz="-6.1323e-9" iyy="2.4460e-6" iyz="2.4541e-9" izz="2.6537e-6"/>
    </inertial>
    <visual>
      <origin rpy="0 0 0" xyz="0 0 0"/>
      <geometry>
        <mesh filename="/home/k/Desktop/Projects/isaacgymenvs_diana7/Arnie/arnie/models/diana_v2_with_hithand/meshes/visual/finger/hit-hand-2-finger-phamed-diana-rot.dae"/>
      </geometry>
      <material name="white"/>
    </visual>
    <collision>
      <origin rpy="0 0 0" xyz="0 0 0"/>
      <geometry>
        <mesh filename="/home/k/Desktop/Projects/isaacgymenvs_diana7/Arnie/arnie/models/diana_v2_with_hithand/meshes/collision/finger/hit-hand-2-finger-phamed.stl"/>
      </geometry>
    </collision>
  </link>
  <!-- +++++ Finger joint 3 Phalanx distalis ++++++ -->
  <joint name="Right_Ring_3" type="revolute">
    <origin rpy="0 0 -1.570796" xyz="0.025 0 0"/>
    <parent link="Right_Ring_Phamed"/>
    <child link="Right_Ring_Phadist"/>
    <axis xyz="0 0 1"/>
    <limit effort="0.35" lower="0.0" upper="1.13446" velocity="3.14"/>
    <!-- Effort limit based on max fingertip force of 10N. Finger tip is approx 3.5cm away from this joint.-->
    <dynamics damping="0.5" friction="0"/>
  </joint>
  <link name="Right_Ring_Phadist">
    <inertial>
      <origin rpy="0 0 0" xyz="0.00072 0.00717 0.0"/>
      <mass value="0.0137"/>
      <inertia ixx="1.5519e-6" ixy="-2.037e-9" ixz="0.0" iyy="8.2972e-7" iyz="3.77e-9" izz="1.5788e-6"/>
    </inertial>
    <visual>
      <origin rpy="0 0 0" xyz="0 0 0"/>
      <geometry>
        <mesh filename="/home/k/Desktop/Projects/isaacgymenvs_diana7/Arnie/arnie/models/diana_v2_with_hithand/meshes/visual/finger/hit-hand-2-finger-phadist-diana-rot.dae"/>
      </geometry>
      <material name="white"/>
    </visual>
    <collision>
      <origin rpy="0 0 0" xyz="0 0 0"/>
      <geometry>
        <mesh filename="/home/k/Desktop/Projects/isaacgymenvs_diana7/Arnie/arnie/models/diana_v2_with_hithand/meshes/collision/finger/hit-hand-2-finger-phadist.stl"/>
      </geometry>
    </collision>
  </link>
  <!-- +++++ Finger base joint 0 ++++++ -->
  <joint name="Right_Little_0" type="revolute">
    <!-- joint origin in parent link frame -->
    <origin rpy="-2.967060 -1.570796 0.000000" xyz="0.000971571 -0.0433963 0.093583545"/>
    <parent link="base_link_hithand"/>
    <child link="Right_Little_Basecover"/>
    <axis xyz="0 0 1"/>
    <limit effort="15" lower="-0.261799" upper="0.261799" velocity="3.14"/>
    <dynamics damping="0.5" friction="0"/>
  </joint>
  <link name="Right_Little_Basecover">
    <inertial>
      <origin rpy="0 0 0" xyz="0.02749 0 0"/>
      <mass value="0.0176"/>
      <inertia ixx="1.3450e-6" ixy="0.0" ixz="-1.8183e-7" iyy="1.9874e-6" iyz="0.0" izz="1.0419e-6"/>
    </inertial>
    <visual>
      <origin rpy="0 0 0" xyz="0 0 0"/>
      <geometry>
        <mesh filename="/home/k/Desktop/Projects/isaacgymenvs_diana7/Arnie/arnie/models/diana_v2_with_hithand/meshes/visual/finger/hit-hand-2-finger-basecover.dae"/>
      </geometry>
      <material name="white"/>
    </visual>
    <collision>
      <origin rpy="0 0 0" xyz="0 0 0"/>
      <geometry name="hithand_Little_base_cover">
        <cylinder length="0.001" radius="0.001"/>
      </geometry>
    </collision>
  </link>
  <!-- +++++ Finger joint 1, Link: Phalanx proximalis ++++++ -->
  <joint name="Right_Little_1" type="revolute">
    <origin rpy="1.5708 0 0" xyz="0 0 0 "/>
    <parent link="Right_Little_Basecover"/>
    <child link="Right_Little_Phaprox"/>
    <axis xyz="0 0 1"/>
    <limit effort="1.15" lower="0.0" upper="1.48353" velocity="3.14"/>
    <!-- Effort limit based on max fingertip force of 10N. Finger tip is approx 11.5cm away from this joint.-->
    <dynamics damping="0.5" friction="0"/>
  </joint>
  <link name="Right_Little_Phaprox">
    <inertial>
      <origin rpy="0 0 0" xyz="0.03076 0.00297 0"/>
      <mass value="0.0232"/>
      <inertia ixx="2.5326e-6" ixy="-9.2551e-7" ixz="-4.0954e-8" iyy="6.9625e-6" iyz="-9.38e-9" izz="7.9108e-6"/>
    </inertial>
    <visual>
      <origin rpy="0 0 0" xyz="0 0 0"/>
      <geometry>
        <mesh filename="/home/k/Desktop/Projects/isaacgymenvs_diana7/Arnie/arnie/models/diana_v2_with_hithand/meshes/visual/finger/hit-hand-2-finger-phaprox-diana-rot.dae"/>
      </geometry>
      <material name="white"/>
    </visual>
    <collision>
      <origin rpy="0 0 0" xyz="0 0 0"/>
      <geometry>
        <mesh filename="/home/k/Desktop/Projects/isaacgymenvs_diana7/Arnie/arnie/models/diana_v2_with_hithand/meshes/collision/finger/hit-hand-2-finger-phaprox.stl"/>
      </geometry>
    </collision>
  </link>
  <!-- +++++ Finger joint 2 Phalanx medialis ++++++ -->
  <joint name="Right_Little_2" type="revolute">
    <origin rpy="0 0 0" xyz="0.055 0 0"/>
    <parent link="Right_Little_Phaprox"/>
    <child link="Right_Little_Phamed"/>
    <axis xyz="0 0 1"/>
    <limit effort="0.6" lower="0.0" upper="1.13446" velocity="3.14"/>
    <!-- Effort limit based on max fingertip force of 10N. Finger tip is approx 6cm away from this joint.-->
    <dynamics damping="0.5" friction="0"/>
  </joint>
  <link name="Right_Little_Phamed">
    <inertial>
      <origin rpy="0 0 0" xyz="0.0097 -0.00036 0"/>
      <mass value="0.0158"/>
      <inertia ixx="1.1852e-6" ixy="-2.8845e-8" ixz="-6.1323e-9" iyy="2.4460e-6" iyz="2.4541e-9" izz="2.6537e-6"/>
    </inertial>
    <visual>
      <origin rpy="0 0 0" xyz="0 0 0"/>
      <geometry>
        <mesh filename="/home/k/Desktop/Projects/isaacgymenvs_diana7/Arnie/arnie/models/diana_v2_with_hithand/meshes/visual/finger/hit-hand-2-finger-phamed-diana-rot.dae"/>
      </geometry>
      <material name="white"/>
    </visual>
    <collision>
      <origin rpy="0 0 0" xyz="0 0 0"/>
      <geometry>
        <mesh filename="/home/k/Desktop/Projects/isaacgymenvs_diana7/Arnie/arnie/models/diana_v2_with_hithand/meshes/collision/finger/hit-hand-2-finger-phamed.stl"/>
      </geometry>
    </collision>
  </link>
  <!-- +++++ Finger joint 3 Phalanx distalis ++++++ -->
  <joint name="Right_Little_3" type="revolute">
    <origin rpy="0 0 -1.570796" xyz="0.025 0 0"/>
    <parent link="Right_Little_Phamed"/>
    <child link="Right_Little_Phadist"/>
    <axis xyz="0 0 1"/>
    <limit effort="0.35" lower="0.0" upper="1.13446" velocity="3.14"/>
    <!-- Effort limit based on max fingertip force of 10N. Finger tip is approx 3.5cm away from this joint.-->
    <dynamics damping="0.5" friction="0"/>
  </joint>
  <link name="Right_Little_Phadist">
    <inertial>
      <origin rpy="0 0 0" xyz="0.00072 0.00717 0.0"/>
      <mass value="0.0137"/>
      <inertia ixx="1.5519e-6" ixy="-2.037e-9" ixz="0.0" iyy="8.2972e-7" iyz="3.77e-9" izz="1.5788e-6"/>
    </inertial>
    <visual>
      <origin rpy="0 0 0" xyz="0 0 0"/>
      <geometry>
        <mesh filename="/home/k/Desktop/Projects/isaacgymenvs_diana7/Arnie/arnie/models/diana_v2_with_hithand/meshes/visual/finger/hit-hand-2-finger-phadist-diana-rot.dae"/>
      </geometry>
      <material name="white"/>
    </visual>
    <collision>
      <origin rpy="0 0 0" xyz="0 0 0"/>
      <geometry>
        <mesh filename="/home/k/Desktop/Projects/isaacgymenvs_diana7/Arnie/arnie/models/diana_v2_with_hithand/meshes/collision/finger/hit-hand-2-finger-phadist.stl"/>
      </geometry>
    </collision>
  </link>
</robot>

