<?xml version="1.0" ?>
<robot name="arnie">
  <material name="Blue">
    <color rgba="0.0 0.0 0.8 1.0"/>
  </material>
  <material name="Green">
    <color rgba="0.0 0.8 0.0 1.0"/>
  </material>
  <material name="Grey">
    <color rgba="0.2 0.2 0.2 1.0"/>
  </material>
  <material name="LightGrey">
    <color rgba="0.6 0.6 0.6 1.0"/>
  </material>
  <material name="Red">
    <color rgba="0.8 0.0 0.0 1.0"/>
  </material>
  <material name="White">
    <color rgba="1.0 1.0 1.0 1.0"/>
  </material>
  <link name="left_base">
    <inertial>
      <origin rpy="0 0 0" xyz="0.00153097191906452 0.00152031034664837 0.0524230280849149"/>
      <mass value="1.33110743457779"/>
      <inertia ixx="0.00695879790529406" ixy="9.99328685258342E-05" ixz="7.99577031212481E-05" iyy="0.00695365531716522" iyz="7.90796997368543E-05" izz="0.00729823323321907"/>
    </inertial>
    <visual>
      <origin rpy="0 0 0" xyz="0 0 0"/>
      <geometry>
        <mesh filename="/home/soumya.mondal/Desktop/IsaacGymEnvs/assets/urdf/arnie/meshes/visual/base.obj"/>
      </geometry>
      <material name="">
        <color rgba="0.796078431372549 0.823529411764706 0.937254901960784 1"/>
      </material>
    </visual>
    <collision>
      <origin rpy="0 0 0" xyz="0 0 0"/>
      <geometry>
        <mesh filename="/home/soumya.mondal/Desktop/IsaacGymEnvs/assets/urdf/arnie/meshes/collision/link0.stl"/>
      </geometry>
    </collision>
  </link>
  <link name="left_link_1">
    <inertial>
      <origin rpy="0 0 0" xyz="5.5234067920554E-05  -0.0254878204920178 0.0355441421264809"/>
      <mass value="1.09025546409174"/>
      <inertia ixx="0.00585031196428369" ixy="1.4630349447555E-07" ixz="1.35351687162397E-06" iyy="0.00645496952227061" iyz="-0.00104800484741808" izz="0.00459531291521244"/>
    </inertial>
    <visual>
      <origin rpy="3.1415926531795866 0 0" xyz="0 0 0"/>
      <geometry>
        <mesh filename="/home/soumya.mondal/Desktop/IsaacGymEnvs/assets/urdf/arnie/meshes/visual/link_1.obj"/>
      </geometry>
      <material name="">
        <color rgba="0.796078431372549 0.823529411764706 0.937254901960784 1"/>
      </material>
    </visual>
    <collision>
      <origin rpy="3.1415926531795866 0 0" xyz="0 0 0"/>
      <geometry>
        <mesh filename="/home/soumya.mondal/Desktop/IsaacGymEnvs/assets/urdf/arnie/meshes/collision/link1.stl"/>
      </geometry>
    </collision>
  </link>
  <joint name="left_joint_1" type="revolute">
    <origin rpy="-3.1415926535795866 0.0 -0.0" xyz="0.0 -2.9150689157e-12 0.2856"/>
    <parent link="left_base"/>
    <child link="left_link_1"/>
    <axis xyz="0 0 1"/>
    <limit effort="235" lower="-3.12" upper="3.12" velocity="2.618"/>
  </joint>
  <link name="left_link_2">
    <inertial>
      <origin rpy="0 0 0" xyz="-3.62724763868157E-06 -0.0292741005087307 -0.041280769252073"/>
      <mass value="1.09515454908799"/>
      <inertia ixx="0.00575817488413533" ixy="4.92454490330888E-07" ixz="-5.75758988171004E-07" iyy="0.00452592941277235" iyz="0.00135206824645357" izz="0.0058904584276842"/>
    </inertial>
    <visual>
      <origin rpy="0 0 0" xyz="0 0 0"/>
      <geometry>
        <mesh filename="/home/soumya.mondal/Desktop/IsaacGymEnvs/assets/urdf/arnie/meshes/visual/link_2.obj"/>
      </geometry>
      <material name="">
        <color rgba="0.980392156862745 0.980392156862745 0.470588235294118 1"/>
      </material>
    </visual>
    <collision>
      <origin rpy="0 0 0" xyz="0 0 0"/>
      <geometry>
        <mesh filename="/home/soumya.mondal/Desktop/IsaacGymEnvs/assets/urdf/arnie/meshes/collision/link2.stl"/>
      </geometry>
    </collision>
  </link>
  <joint name="left_joint_2" type="revolute">
    <origin rpy="1.57079632679 -0.0 0.0" xyz="0.0 -0.0 0.0"/>
    <parent link="left_link_1"/>
    <child link="left_link_2"/>
    <axis xyz="0 0 1"/>
    <limit effort="235" lower="-1.57" upper="1.57" velocity="2.618"/>
  </joint>
  <link name="left_link_3">
    <inertial>
      <origin rpy="0 3.1415926531795866 3.1415926531795866" xyz="0.0114318213510691 -0.0101707598694861 0.15131695375217"/>
      <mass value="2.01686690128149"/>
      <inertia ixx="0.0362470020041464" ixy="-0.00099203786071914" ixz="-0.00494440140493448" iyy="0.0374857206758098" iyz="-0.00313859974095155" izz="0.00905850119342719"/>
    </inertial>
    <visual>
      <origin rpy="3.1415926531795866 0 0" xyz="0 0 0"/>
      <geometry>
        <mesh filename="/home/soumya.mondal/Desktop/IsaacGymEnvs/assets/urdf/arnie/meshes/visual/link_3.obj"/>
      </geometry>
      <material name="">
        <color rgba="0.898039215686275 0.917647058823529 0.929411764705882 1"/>
      </material>
    </visual>
    <collision>
      <origin rpy="3.1415926531795866 0 0" xyz="0 0 0"/>
      <geometry>
        <mesh filename="/home/soumya.mondal/Desktop/IsaacGymEnvs/assets/urdf/arnie/meshes/collision/link3.stl"/>
      </geometry>
    </collision>
  </link>
  <joint name="left_joint_3" type="revolute">
    <origin rpy="-1.57079632679 0.0 0.0" xyz="0.0 -0.4586 -2.24557565126e-12"/>
    <parent link="left_link_2"/>
    <child link="left_link_3"/>
    <axis xyz="0 0 1"/>
    <limit effort="111" lower="-3.12" upper="3.12" velocity="3.1416"/>
  </joint>
  <link name="left_link_4">
    <inertial>
      <origin rpy="0 0 0" xyz="-0.0240716370537192 -0.0235631728011761 -0.0366858174253844"/>
      <mass value="0.849743349506889"/>
      <inertia ixx="0.00313444335639628" ixy="-0.000681243351041131" ixz="0.000725380047812207" iyy="0.00333717642442852" iyz="0.000771057559109157" izz="0.0034847726349841"/>
    </inertial>
    <visual>
      <origin rpy="0 0 0" xyz="0 0 0"/>
      <geometry>
        <mesh filename="/home/soumya.mondal/Desktop/IsaacGymEnvs/assets/urdf/arnie/meshes/visual/link_4.obj"/>
      </geometry>
      <material name="">
        <color rgba="0.898039215686275 0.917647058823529 0.929411764705882 1"/>
      </material>
    </visual>
    <collision>
      <origin rpy="0 0 0" xyz="0 0 0"/>
      <geometry>
        <mesh filename="/home/soumya.mondal/Desktop/IsaacGymEnvs/assets/urdf/arnie/meshes/collision/link4.stl"/>
      </geometry>
    </collision>
  </link>
  <joint name="left_joint_4" type="revolute">
    <origin rpy="1.57079632679 -0.0 0.0" xyz="0.065 -0.0 0.0"/>
    <parent link="left_link_3"/>
    <child link="left_link_4"/>
    <axis xyz="0 0 1"/>
    <limit effort="111" lower="0" upper="3.05" velocity="3.1416"/>
  </joint>
  <link name="left_link_5">
    <inertial>
      <origin rpy="0 3.1415926531795866 3.1415926531795866" xyz="-0.00867148011164554 0.0383499684802812 0.188626"/>
      <mass value="1.20580396965245"/>
      <inertia ixx="0.0218436427570802" ixy="-0.000309747330693722" ixz="0.00089039094846826" iyy="0.0205896836785318" iyz="0.00493573923914426" izz="0.00372270106038425"/>
    </inertial>
    <visual>
      <origin rpy="3.1415926531795866 0 0" xyz="0 0 -0.02162"/>
      <geometry>
        <mesh filename="/home/soumya.mondal/Desktop/IsaacGymEnvs/assets/urdf/arnie/meshes/visual/link_5.obj"/>
      </geometry>
      <material name="">
        <color rgba="0.898039215686275 0.917647058823529 0.929411764705882 1"/>
      </material>
    </visual>
    <collision>
      <origin rpy="3.1415926531795866 0 0" xyz="0 0 -0.02162"/>
      <geometry>
        <mesh filename="/home/soumya.mondal/Desktop/IsaacGymEnvs/assets/urdf/arnie/meshes/collision/link5.stl"/>
      </geometry>
    </collision>
  </link>
  <joint name="left_joint_5" type="revolute">
    <origin rpy="-1.57079632679 0.0 0.0" xyz="-0.0528 -0.4554 -2.22990656691e-12"/>
    <parent link="left_link_4"/>
    <child link="left_link_5"/>
    <axis xyz="0 0 1"/>
    <limit effort="54" lower="-3.12" upper="3.12" velocity="2.618"/>
  </joint>
  <link name="left_link_6">
    <inertial>
      <origin rpy="0 3.1415926531795866 3.1415926531795866" xyz="0.045897226241036 0.00848579821002571 -0.0078257811617596"/>
      <mass value="0.847157564562275"/>
      <inertia ixx="0.00286926864109097" ixy="-0.000341664135091818" ixz="-0.000318082297486923" iyy="0.0043294660443987" iyz="-5.82962380662208E-05" izz="0.00437292566725527"/>
    </inertial>
    <visual>
      <origin rpy="3.1415926531795866 0 3.14159265359" xyz="0 0 0"/>
      <geometry>
        <mesh filename="/home/soumya.mondal/Desktop/IsaacGymEnvs/assets/urdf/arnie/meshes/visual/link_6.obj"/>
      </geometry>
      <material name="">
        <color rgba="0.980392156862745 0.980392156862745 0.470588235294118 1"/>
      </material>
    </visual>
    <collision>
      <origin rpy="3.1415926531795866 0 3.14159265359" xyz="0 0 0"/>
      <geometry>
        <mesh filename="/home/soumya.mondal/Desktop/IsaacGymEnvs/assets/urdf/arnie/meshes/collision/link6.stl"/>
      </geometry>
    </collision>
  </link>
  <joint name="left_joint_6" type="revolute">
    <origin rpy="1.57079632679 -1.0206823934513925e-11 -3.141592653589793" xyz="-0.0122 0.0 0.0"/>
    <parent link="left_link_5"/>
    <child link="left_link_6"/>
    <axis xyz="0 0 1"/>
    <limit effort="54" lower="-3.12" upper="0.52" velocity="2.618"/>
  </joint>
  <link name="left_link_7">
    <inertial>
      <origin rpy="0 0 0" xyz="0.00117005127509708 5.03191940906655E-06 0.0151381784822231"/>
      <mass value="0.233956150459573"/>
      <inertia ixx="0.000142027360977168" ixy="1.76426389345981E-08" ixz="2.14635741626268E-07" iyy="0.000134421724783865" iyz="-1.29988689037464E-09" izz="0.000240242798572463"/>
    </inertial>
    <visual>
      <origin rpy="0 0 0" xyz="0 0 0"/>
      <geometry>
        <mesh filename="/home/soumya.mondal/Desktop/IsaacGymEnvs/assets/urdf/arnie/meshes/visual/link_7.obj"/>
      </geometry>
      <material name="">
        <color rgba="0.898039215686275 0.917647058823529 0.929411764705882 1"/>
      </material>
    </visual>
    <collision>
      <origin rpy="0 0 0" xyz="0 0 0"/>
      <geometry>
        <mesh filename="/home/soumya.mondal/Desktop/IsaacGymEnvs/assets/urdf/arnie/meshes/collision/link7.stl"/>
      </geometry>
    </collision>
  </link>
  <joint name="left_joint_7" type="revolute">
    <origin rpy="-1.57079632679 0.0 0.0" xyz="0.087 -0.1169 -5.72411237751e-13"/>
    <parent link="left_link_6"/>
    <child link="left_link_7"/>
    <axis xyz="0 0 1"/>
    <limit effort="54" lower="-3.12" upper="3.12" velocity="3.1416"/>
  </joint>
  <link name="left_link_7_fake">
  </link>
  <joint name="left_link_7_to_left_link_7_fake" type="fixed">
    <parent link="left_link_7" />
    <child link="left_link_7_fake" />
    <origin rpy="3.1415926 0 0" xyz="0 0 0" />
  </joint>
  <link name="forearm">
    <inertial>
      <origin rpy="0 0 0" xyz="0 0 0.09"/>
      <!-- <mass value="3.0"/> -->
      <mass value="3.0"/>

      <inertia ixx="1.0" ixy="0.0" ixz="0.0" iyy="1.0" iyz="0.0" izz="1.0"/>
    </inertial>
    <visual>
      <origin rpy="0 0 0" xyz="0 0 0"/>
      <geometry name="shadow_forearm_geom">
        <mesh filename="/home/soumya.mondal/Desktop/Projects/Arnie/arnie/models/Arnie/meshes/forearm.dae" scale="0.1 0.1 0.1"/>
      </geometry>
      <material name="Grey"/>
    </visual>
    <collision>
      <origin rpy="0 0 0" xyz="0 0 0.09"/>
      <geometry name="shadow_forearm_collision">
        <cylinder length="0.180" radius="0.06"/>
      </geometry>
    </collision>
  </link>
  <joint name="forearm" type="fixed">
    <parent link="left_link_7_fake" />
    <child link="forearm" />
    <!-- <origin rpy="-1.57 0 0" xyz="0 0 -0.05" /> -->
      <origin rpy="0 0 0" xyz="0 0 0.05" />
  </joint>
  <link name="wrist">
    <inertial>
      <origin rpy="0 0 0" xyz="0 0.0 0.0"/>
      <mass value="0.1"/>
      <!-- <inertia ixx="0.120" ixy="0.0" ixz="0.0" iyy="0.148" iyz="0.0" izz="0.0438"/> -->
      <inertia ixx="0.120" ixy="0.0" ixz="0.0" iyy="0.148" iyz="0.0" izz="0.0438"/>

    </inertial>
    <visual>
      <origin rpy="0 0 0" xyz="0 0 0"/>
      <geometry name="wrist_visual">
        <mesh filename="/home/soumya.mondal/Desktop/Projects/Arnie/arnie/models/Arnie/meshes/wrist.dae" scale="0.1 0.1 0.1"/>
      </geometry>
      <material name="LightGrey"/>
    </visual>
    <collision>
      <origin rpy="0 0 0" xyz="0 0 0"/>
      <geometry name="wrist_collision_geom">
        <box size="0.02 0.02 0.02"/>
      </geometry>
    </collision>
  </link>
  <joint name="WRJ2" type="revolute">
    <parent link="forearm"/>
    <child link="wrist"/>
      <!-- <origin rpy="0 0 -3.14" xyz="0 -0.010  0.213"/> -->
    <origin rpy="0 0 0" xyz="0 -0.010 0.213"/>
    <axis xyz="0 1 0"/>
    <limit effort="5" lower="-0.52359877559829882" upper="0.17453292519943295" velocity="1.0"/>
    <dynamics damping="100.5"/>
  </joint>
  <link name="palm">
    <inertial>
      <origin rpy="0 0 0" xyz="0 0 0.035"/>
      <mass value="0.3"/>
      <inertia ixx="0.5" ixy="0.0" ixz="0.0" iyy="0.5" iyz="0.0" izz="0.3"/>
    </inertial>
    <visual>
      <origin rpy="0 0 0" xyz="0 0 0"/>
      <geometry name="palm_visual">
        <mesh filename="/home/soumya.mondal/Desktop/Projects/Arnie/arnie/models/Arnie/meshes/palm.dae" scale="0.1 0.1 0.1"/>
      </geometry>
      <material name="Grey"/>
    </visual>
    <collision>
      <origin rpy="0 0 0" xyz="0.005 0 0.035"/>
      <geometry name="palm_collision_geom">
        <box size="0.05 0.02 0.07"/>
      </geometry>
    </collision>
  </link>
  <joint name="WRJ1" type="revolute">
    <parent link="wrist"/>
    <child link="palm"/>
    <origin rpy="0 0 0" xyz="0 0 0.034"/>
    <axis xyz="1 0 0"/>
    <limit effort="5" lower="-0.78539816339744828" upper="0.6108652381980153" velocity="1.0"/>
    <dynamics damping="100.5"/>
  </joint>
  <link name="ffknuckle">
    <inertial>
      <origin rpy="0 0 0" xyz="0 0 0"/>
      <mass value="0.008"/>
      <inertia ixx="0.0" ixy="0.0" ixz="0.0" iyy="0.1" iyz="0.0" izz="0.0"/>
    </inertial>
    <visual>
      <origin rpy="0 0 0" xyz="0 0 0.0005"/>
      <geometry name="knuckle_visual">
        <mesh filename="/home/soumya.mondal/Desktop/Projects/Arnie/arnie/models/Arnie/meshes/knuckle.dae" scale="0.1 0.1 0.1"/>
      </geometry>
      <material name="LightGrey"/>
    </visual>
    <collision>
      <origin rpy="0 0 0" xyz="0 0 0"/>
      <geometry name="knuckle_collision_geom">
        <box size="0.005 0.005 0.005"/>
      </geometry>
    </collision>
  </link>
  <joint name="FFJ4" type="revolute">
    <parent link="palm"/>
    <child link="ffknuckle"/>
    <origin rpy="0 0 0" xyz="0.033 0 0.095"/>
    <axis xyz="0 -1 0"/>
    <limit effort="100" lower="-0.43633231299858238" upper="0.43633231299858238" velocity="1.0"/>
    <dynamics damping="50.5"/>
  </joint>
  <link name="ffproximal">
    <inertial>
      <mass value="0.014"/>
      <origin xyz="0 0 0.0225"/>
      <inertia ixx="0.1" ixy="0.0" ixz="0.0" iyy="0.1" iyz="0.0" izz="0.0"/>
    </inertial>
    <visual>
      <origin rpy="0 0 0" xyz="0 0 0"/>
      <geometry name="proximal_visual">
        <mesh filename="/home/soumya.mondal/Desktop/Projects/Arnie/arnie/models/Arnie/meshes/F3.dae" scale="0.1 0.1 0.1"/>
      </geometry>
      <material name="Grey"/>
    </visual>
    <collision>
      <origin rpy="0 0 0 " xyz="0 0 0.025"/>
      <geometry name="proximal_collision_geom">
        <box size="0.008 0.008 0.04"/>
      </geometry>
    </collision>
  </link>
  <joint name="FFJ3" type="revolute">
    <parent link="ffknuckle"/>
    <child link="ffproximal"/>
    <origin rpy="0 0 0" xyz="0 0 0"/>
    <axis xyz="1 0 0"/>
    <limit effort="100" lower="0" upper="1.57079632679" velocity="1.0"/>
    <dynamics damping="50.5"/>
  </joint>
  <link name="ffmiddle">
    <inertial>
      <origin rpy="0 0 0" xyz="0 0 0.0125"/>
      <mass value="0.012"/>
      <inertia ixx="0.1" ixy="0.0" ixz="0.0" iyy="0.1" iyz="0.0" izz="0.0"/>
    </inertial>
    <visual>
      <origin rpy="0 0 0" xyz="0 0 0"/>
      <geometry name="middle_visual">
        <mesh filename="/home/soumya.mondal/Desktop/Projects/Arnie/arnie/models/Arnie/meshes/F2.dae" scale="0.1 0.1 0.1"/>
      </geometry>
      <material name="Grey"/>
    </visual>
    <collision>
      <origin rpy="0 0 0" xyz="0 0 0.0125"/>
      <geometry name="middle_collision_geom">
        <box size="0.008 0.008 0.015"/>
      </geometry>
    </collision>
  </link>
  <joint name="FFJ2" type="revolute">
    <parent link="ffproximal"/>
    <child link="ffmiddle"/>
    <origin rpy="0 0 0" xyz="0 0 0.045"/>
    <axis xyz="1 0 0"/>
    <limit effort="100" lower="0" upper="1.57079632679" velocity="1.0"/>
    <dynamics damping="50.5"/>
  </joint>
  <link name="ffdistal">
    <inertial>
      <mass value="0.010"/>
      <origin xyz="0 0 0.013"/>
      <inertia ixx="0.1" ixy="0.0" ixz="0.0" iyy="0.1" iyz="0.0" izz="0.0"/>
    </inertial>
    <visual>
      <origin rpy="0 0 0" xyz="0 0 0"/>
      <geometry name="distal_visual">
        <mesh filename="/home/soumya.mondal/Desktop/Projects/Arnie/arnie/models/Arnie/meshes/distal_ellipsoid.dae" scale="0.1 0.1 0.1"/>
      </geometry>
      <material name="Grey"/>
    </visual>
    <collision>
      <origin rpy="0 0 0" xyz="0 0 0"/>
      <geometry name="distal_collision_geom">
        <mesh filename="/home/soumya.mondal/Desktop/Projects/Arnie/arnie/models/Arnie/meshes/distal_ellipsoid.dae" scale="0.1 0.1 0.1"/>
      </geometry>
    </collision>
  </link>
  <joint name="FFJ1" type="revolute">
    <parent link="ffmiddle"/>
    <child link="ffdistal"/>
    <origin rpy="0 0 0" xyz="0 0 0.025"/>
    <axis xyz="1 0 0"/>
    <limit effort="100" lower="0" upper="1.57079632679" velocity="1.0"/>
    <dynamics damping="50.5"/>
  </joint>
  <link name="fftip">
    <inertial>
      <mass value="0.001"/>
      <inertia ixx="0.0" ixy="0.0" ixz="0.0" iyy="0.0" iyz="0.0" izz="0.0"/>
    </inertial>
  </link>
  <joint name="FFtip" type="fixed">
    <parent link="ffdistal"/>
    <child link="fftip"/>
    <origin rpy="0 0 0" xyz="0 0 0.026"/>
  </joint>
  <link name="mfknuckle">
    <inertial>
      <origin rpy="0 0 0" xyz="0 0 0"/>
      <mass value="0.008"/>
      <inertia ixx="0.0" ixy="0.0" ixz="0.0" iyy="0.1" iyz="0.0" izz="0.0"/>
    </inertial>
    <visual>
      <origin rpy="0 0 0" xyz="0 0 0.0005"/>
      <geometry name="knuckle_visual">
        <mesh filename="/home/soumya.mondal/Desktop/Projects/Arnie/arnie/models/Arnie/meshes/knuckle.dae" scale="0.1 0.1 0.1"/>
      </geometry>
      <material name="LightGrey"/>
    </visual>
    <collision>
      <origin rpy="0 0 0" xyz="0 0 0"/>
      <geometry name="knuckle_collision_geom">
        <box size="0.005 0.005 0.005"/>
      </geometry>
    </collision>
  </link>
  <joint name="MFJ4" type="revolute">
    <parent link="palm"/>
    <child link="mfknuckle"/>
    <origin rpy="0 0 0" xyz="0.011 0 0.099"/>
    <axis xyz="0 -1 0"/>
    <limit effort="100" lower="-0.43633231299858238" upper="0.43633231299858238" velocity="1.0"/>
    <dynamics damping="50.5"/>
  </joint>
  <link name="mfproximal">
    <inertial>
      <mass value="0.014"/>
      <origin xyz="0 0 0.0225"/>
      <inertia ixx="0.1" ixy="0.0" ixz="0.0" iyy="0.1" iyz="0.0" izz="0.0"/>
    </inertial>
    <visual>
      <origin rpy="0 0 0" xyz="0 0 0"/>
      <geometry name="proximal_visual">
        <mesh filename="/home/soumya.mondal/Desktop/Projects/Arnie/arnie/models/Arnie/meshes/F3.dae" scale="0.1 0.1 0.1"/>
      </geometry>
      <material name="Grey"/>
    </visual>
    <collision>
      <origin rpy="0 0 0 " xyz="0 0 0.025"/>
      <geometry name="proximal_collision_geom">
        <box size="0.008 0.008 0.04"/>
      </geometry>
    </collision>
  </link>
  <joint name="MFJ3" type="revolute">
    <parent link="mfknuckle"/>
    <child link="mfproximal"/>
    <origin rpy="0 0 0" xyz="0 0 0"/>
    <axis xyz="1 0 0"/>
    <limit effort="100" lower="0" upper="1.57079632679" velocity="1.0"/>
    <dynamics damping="50.5"/>
  </joint>
  <link name="mfmiddle">
    <inertial>
      <origin rpy="0 0 0" xyz="0 0 0.0125"/>
      <mass value="0.012"/>
      <inertia ixx="0.1" ixy="0.0" ixz="0.0" iyy="0.1" iyz="0.0" izz="0.0"/>
    </inertial>
    <visual>
      <origin rpy="0 0 0" xyz="0 0 0"/>
      <geometry name="middle_visual">
        <mesh filename="/home/soumya.mondal/Desktop/Projects/Arnie/arnie/models/Arnie/meshes/F2.dae" scale="0.1 0.1 0.1"/>
      </geometry>
      <material name="Grey"/>
    </visual>
    <collision>
      <origin rpy="0 0 0" xyz="0 0 0.0125"/>
      <geometry name="middle_collision_geom">
        <box size="0.008 0.008 0.015"/>
      </geometry>
    </collision>
  </link>
  <joint name="MFJ2" type="revolute">
    <parent link="mfproximal"/>
    <child link="mfmiddle"/>
    <origin rpy="0 0 0" xyz="0 0 0.045"/>
    <axis xyz="1 0 0"/>
    <limit effort="100" lower="0" upper="1.57079632679" velocity="1.0"/>
    <dynamics damping="50.5"/>
  </joint>
  <link name="mfdistal">
    <inertial>
      <mass value="0.010"/>
      <origin xyz="0 0 0.013"/>
      <inertia ixx="0.1" ixy="0.0" ixz="0.0" iyy="0.1" iyz="0.0" izz="0.0"/>
    </inertial>
    <visual>
      <origin rpy="0 0 0" xyz="0 0 0"/>
      <geometry name="distal_visual">
        <mesh filename="/home/soumya.mondal/Desktop/Projects/Arnie/arnie/models/Arnie/meshes/F1.dae" scale="0.1 0.1 0.1"/>
      </geometry>
      <material name="Grey"/>
    </visual>
    <collision>
      <origin rpy="0 0 0" xyz="0 0 0"/>
      <geometry name="distal_collision_geom">
        <mesh filename="/home/soumya.mondal/Desktop/Projects/Arnie/arnie/models/Arnie/meshes/F1.dae" scale="0.1 0.1 0.1"/>
      </geometry>
    </collision>
  </link>
  <joint name="MFJ1" type="revolute">
    <parent link="mfmiddle"/>
    <child link="mfdistal"/>
    <origin rpy="0 0 0" xyz="0 0 0.025"/>
    <axis xyz="1 0 0"/>
    <limit effort="100" lower="0" upper="1.57079632679" velocity="1.0"/>
    <dynamics damping="50.5"/>
  </joint>
  <link name="mftip">
    <inertial>
      <mass value="0.001"/>
      <inertia ixx="0.0" ixy="0.0" ixz="0.0" iyy="0.0" iyz="0.0" izz="0.0"/>
    </inertial>
  </link>
  <joint name="MFtip" type="fixed">
    <parent link="mfdistal"/>
    <child link="mftip"/>
    <origin rpy="0 0 0" xyz="0 0 0.026"/>
  </joint>
  <link name="rfknuckle">
    <inertial>
      <origin rpy="0 0 0" xyz="0 0 0"/>
      <mass value="0.008"/>
      <inertia ixx="0.0" ixy="0.0" ixz="0.0" iyy="0.1" iyz="0.0" izz="0.0"/>
    </inertial>
    <visual>
      <origin rpy="0 0 0" xyz="0 0 0.0005"/>
      <geometry name="knuckle_visual">
        <mesh filename="/home/soumya.mondal/Desktop/Projects/Arnie/arnie/models/Arnie/meshes/knuckle.dae" scale="0.1 0.1 0.1"/>
      </geometry>
      <material name="LightGrey"/>
    </visual>
    <collision>
      <origin rpy="0 0 0" xyz="0 0 0"/>
      <geometry name="knuckle_collision_geom">
        <box size="0.005 0.005 0.005"/>
      </geometry>
    </collision>
  </link>
  <joint name="RFJ4" type="revolute">
    <parent link="palm"/>
    <child link="rfknuckle"/>
    <origin rpy="0 0 0" xyz="-0.011 0 0.095"/>
    <axis xyz="0 1 0"/>
    <limit effort="100" lower="-0.43633231299858238" upper="0.43633231299858238" velocity="1.0"/>
    <dynamics damping="50.5"/>
  </joint>
  <link name="rfproximal">
    <inertial>
      <mass value="0.014"/>
      <origin xyz="0 0 0.0225"/>
      <inertia ixx="0.1" ixy="0.0" ixz="0.0" iyy="0.1" iyz="0.0" izz="0.0"/>
    </inertial>
    <visual>
      <origin rpy="0 0 0" xyz="0 0 0"/>
      <geometry name="proximal_visual">
        <mesh filename="/home/soumya.mondal/Desktop/Projects/Arnie/arnie/models/Arnie/meshes/F3.dae" scale="0.1 0.1 0.1"/>
      </geometry>
      <material name="Grey"/>
    </visual>
    <collision>
      <origin rpy="0 0 0 " xyz="0 0 0.025"/>
      <geometry name="proximal_collision_geom">
        <box size="0.008 0.008 0.04"/>
      </geometry>
    </collision>
  </link>
  <joint name="RFJ3" type="revolute">
    <parent link="rfknuckle"/>
    <child link="rfproximal"/>
    <origin rpy="0 0 0" xyz="0 0 0"/>
    <axis xyz="1 0 0"/>
    <limit effort="100" lower="0" upper="1.57079632679" velocity="1.0"/>
    <dynamics damping="50.5"/>
  </joint>
  <link name="rfmiddle">
    <inertial>
      <origin rpy="0 0 0" xyz="0 0 0.0125"/>
      <mass value="0.012"/>
      <inertia ixx="0.1" ixy="0.0" ixz="0.0" iyy="0.1" iyz="0.0" izz="0.0"/>
    </inertial>
    <visual>
      <origin rpy="0 0 0" xyz="0 0 0"/>
      <geometry name="middle_visual">
        <mesh filename="/home/soumya.mondal/Desktop/Projects/Arnie/arnie/models/Arnie/meshes/F2.dae" scale="0.1 0.1 0.1"/>
      </geometry>
      <material name="Grey"/>
    </visual>
    <collision>
      <origin rpy="0 0 0" xyz="0 0 0.0125"/>
      <geometry name="middle_collision_geom">
        <box size="0.008 0.008 0.015"/>
      </geometry>
    </collision>
  </link>
  <joint name="RFJ2" type="revolute">
    <parent link="rfproximal"/>
    <child link="rfmiddle"/>
    <origin rpy="0 0 0" xyz="0 0 0.045"/>
    <axis xyz="1 0 0"/>
    <limit effort="100" lower="0" upper="1.57079632679" velocity="1.0"/>
    <dynamics damping="50.5"/>
  </joint>
  <link name="rfdistal">
    <inertial>
      <mass value="0.010"/>
      <origin xyz="0 0 0.013"/>
      <inertia ixx="0.1" ixy="0.0" ixz="0.0" iyy="0.1" iyz="0.0" izz="0.0"/>
    </inertial>
    <visual>
      <origin rpy="0 0 0" xyz="0 0 0"/>
      <geometry name="distal_visual">
        <mesh filename="/home/soumya.mondal/Desktop/Projects/Arnie/arnie/models/Arnie/meshes/distal_ellipsoid.dae" scale="0.1 0.1 0.1"/>
      </geometry>
      <material name="Grey"/>
    </visual>
    <collision>
      <origin rpy="0 0 0" xyz="0 0 0"/>
      <geometry name="distal_collision_geom">
        <mesh filename="/home/soumya.mondal/Desktop/Projects/Arnie/arnie/models/Arnie/meshes/distal_ellipsoid.dae" scale="0.1 0.1 0.1"/>
      </geometry>
    </collision>
  </link>
  <joint name="RFJ1" type="revolute">
    <parent link="rfmiddle"/>
    <child link="rfdistal"/>
    <origin rpy="0 0 0" xyz="0 0 0.025"/>
    <axis xyz="1 0 0"/>
    <limit effort="100" lower="0" upper="1.57079632679" velocity="1.0"/>
    <dynamics damping="50.5"/>
  </joint>
  <link name="rftip">
    <inertial>
      <mass value="0.001"/>
      <inertia ixx="0.0" ixy="0.0" ixz="0.0" iyy="0.0" iyz="0.0" izz="0.0"/>
    </inertial>
  </link>
  <joint name="RFtip" type="fixed">
    <parent link="rfdistal"/>
    <child link="rftip"/>
    <origin rpy="0 0 0" xyz="0 0 0.026"/>
  </joint>
  <link name="lfmetacarpal">
    <inertial>
      <origin rpy="0 0 0" xyz="0 0 0.04"/>
      <mass value="0.075"/>
      <inertia ixx="0.1" ixy="0.0" ixz="0.0" iyy="0.1" iyz="0.0" izz="0.1"/>
    </inertial>
    <visual>
      <origin rpy="0 0 0" xyz="0 0 0"/>
      <geometry name="lfmetacarpal_visual">
        <mesh filename="/home/soumya.mondal/Desktop/Projects/Arnie/arnie/models/Arnie/meshes/lfmetacarpal.dae" scale="0.1 0.1 0.1"/>
      </geometry>
      <material name="Grey"/>
    </visual>
    <collision>
      <origin rpy="0 0 0" xyz="0 0 0.04"/>
      <geometry name="lfmetacarpal_collision_geom">
        <box size="0.008 0.008 0.03"/>
      </geometry>
    </collision>
  </link>
  <joint name="LFJ5" type="revolute">
    <parent link="palm"/>
    <child link="lfmetacarpal"/>
    <origin rpy="0 0 0" xyz="-0.033 0 0.02071"/>
    <axis xyz="0.573576436 0 0.819152044"/>
    <limit effort="100" lower="0" upper="0.69813170079773179" velocity="1.0"/>
    <dynamics damping="50.5"/>
  </joint>
  <link name="lfknuckle">
    <inertial>
      <origin rpy="0 0 0" xyz="0 0 0.06579"/>
      <mass value="0.008"/>
      <inertia ixx="0.1" ixy="0.0" ixz="0.0" iyy="0.1" iyz="0.0" izz="0.1"/>
    </inertial>
    <visual>
      <origin rpy="0 0 0" xyz="0 0 0"/>
      <geometry name="knuckle_visual">
        <mesh filename="/home/soumya.mondal/Desktop/Projects/Arnie/arnie/models/Arnie/meshes/knuckle.dae" scale="0.1 0.1 0.1"/>
      </geometry>
      <material name="LightGrey"/>
    </visual>
    <collision>
      <origin rpy="0 0 0" xyz="0 0 0"/>
      <geometry name="knuckle_collision_geom">
        <box size="0.005 0.005 0.005"/>
      </geometry>
    </collision>
  </link>
  <joint name="LFJ4" type="revolute">
    <parent link="lfmetacarpal"/>
    <child link="lfknuckle"/>
    <origin rpy="0 0 0" xyz="0 0 0.06579"/>
    <axis xyz="0 1 0"/>
    <limit effort="100" lower="-0.43633231299858238" upper="0.43633231299858238" velocity="1.0"/>
    <dynamics damping="50.5"/>
  </joint>
  <link name="lfproximal">
    <inertial>
      <mass value="0.014"/>
      <origin xyz="0 0 0.0225"/>
      <inertia ixx="0.1" ixy="0.0" ixz="0.0" iyy="0.1" iyz="0.0" izz="0.0"/>
    </inertial>
    <visual>
      <origin rpy="0 0 0" xyz="0 0 0"/>
      <geometry name="proximal_visual">
        <mesh filename="/home/soumya.mondal/Desktop/Projects/Arnie/arnie/models/Arnie/meshes/F3.dae" scale="0.1 0.1 0.1"/>
      </geometry>
      <material name="Grey"/>
    </visual>
    <collision>
      <origin rpy="0 0 0 " xyz="0 0 0.025"/>
      <geometry name="proximal_collision_geom">
        <box size="0.008 0.008 0.04"/>
      </geometry>
    </collision>
  </link>
  <joint name="LFJ3" type="revolute">
    <parent link="lfknuckle"/>
    <child link="lfproximal"/>
    <origin rpy="0 0 0" xyz="0 0 0"/>
    <axis xyz="1 0 0"/>
    <limit effort="100" lower="0" upper="1.57079632679" velocity="1.0"/>
    <dynamics damping="50.5"/>
  </joint>
  <link name="lfmiddle">
    <inertial>
      <origin rpy="0 0 0" xyz="0 0 0.0125"/>
      <mass value="0.012"/>
      <inertia ixx="0.1" ixy="0.0" ixz="0.0" iyy="0.1" iyz="0.0" izz="0.0"/>
    </inertial>
    <visual>
      <origin rpy="0 0 0" xyz="0 0 0"/>
      <geometry name="middle_visual">
        <mesh filename="/home/soumya.mondal/Desktop/Projects/Arnie/arnie/models/Arnie/meshes/F2.dae" scale="0.1 0.1 0.1"/>
      </geometry>
      <material name="Grey"/>
    </visual>
    <collision>
      <origin rpy="0 0 0" xyz="0 0 0.0125"/>
      <geometry name="middle_collision_geom">
        <box size="0.008 0.008 0.015"/>
      </geometry>
    </collision>
  </link>
  <joint name="LFJ2" type="revolute">
    <parent link="lfproximal"/>
    <child link="lfmiddle"/>
    <origin rpy="0 0 0" xyz="0 0 0.045"/>
    <axis xyz="1 0 0"/>
    <limit effort="100" lower="0" upper="1.57079632679" velocity="1.0"/>
    <dynamics damping="50.5"/>
  </joint>
  <link name="lfdistal">
    <inertial>
      <mass value="0.010"/>
      <origin xyz="0 0 0.013"/>
      <inertia ixx="0.1" ixy="0.0" ixz="0.0" iyy="0.1" iyz="0.0" izz="0.0"/>
    </inertial>
    <visual>
      <origin rpy="0 0 0" xyz="0 0 0"/>
      <geometry name="distal_visual">
        <mesh filename="/home/soumya.mondal/Desktop/Projects/Arnie/arnie/models/Arnie/meshes/F1.dae" scale="0.1 0.1 0.1"/>
      </geometry>
      <material name="Grey"/>
    </visual>
    <collision>
      <origin rpy="0 0 0" xyz="0 0 0"/>
      <geometry name="distal_collision_geom">
        <mesh filename="/home/soumya.mondal/Desktop/Projects/Arnie/arnie/models/Arnie/meshes/F1.dae" scale="0.1 0.1 0.1"/>
      </geometry>
    </collision>
  </link>
  <joint name="LFJ1" type="revolute">
    <parent link="lfmiddle"/>
    <child link="lfdistal"/>
    <origin rpy="0 0 0" xyz="0 0 0.025"/>
    <axis xyz="1 0 0"/>
    <limit effort="100" lower="0" upper="1.57079632679" velocity="1.0"/>
    <dynamics damping="50.5"/>
  </joint>
  <link name="lftip">
    <inertial>
      <mass value="0.001"/>
      <inertia ixx="0.0" ixy="0.0" ixz="0.0" iyy="0.0" iyz="0.0" izz="0.0"/>
    </inertial>
  </link>
  <joint name="LFtip" type="fixed">
    <parent link="lfdistal"/>
    <child link="lftip"/>
    <origin rpy="0 0 0" xyz="0 0 0.026"/>
  </joint>
  <link name="thbase">
    <inertial>
      <mass value="0.010"/>
      <origin rpy="0 0 0" xyz="0 0 0"/>
      <inertia ixx="0.0" ixy="0.0" ixz="0.0" iyy="0.0" iyz="0.0" izz="0.1"/>
    </inertial>
    <visual>
      <origin rpy="0 0 0" xyz="0 0 0"/>
      <geometry name="thbase_visual">
        <box size="0.001 0.001 0.001"/>
      </geometry>
      <material name="shadow_thbase_material">
        <color rgba="0.5 0.5 0.5 1.0"/>
      </material>
    </visual>
    <collision>
      <origin rpy="0 0 0 " xyz="0 0 0"/>
      <geometry name="thbase_collision_geom">
        <box size="0.001 0.001 0.001"/>
      </geometry>
    </collision>
  </link>
  <joint name="THJ5" type="revolute">
    <parent link="palm"/>
    <child link="thbase"/>
    <origin rpy="0 0.785398163397 0" xyz="0.034 -0.0085 0.029"/>
    <axis xyz="0 0 -1.0"/>
    <limit effort="100" lower="-1.047" upper="1.047" velocity="1.0"/>
    <dynamics damping="50.5"/>
  </joint>
  <link name="thproximal">
    <inertial>
      <mass value="0.016"/>
      <origin rpy="0 0 0" xyz="0 0 0.019"/>
      <inertia ixx="0.1" ixy="0.0" ixz="0.0" iyy="0.1" iyz="0.0" izz="0.1"/>
    </inertial>
    <visual>
      <origin rpy="0 0 0" xyz="0 0 0"/>
      <geometry name="thproximal_visual">
        <mesh filename="/home/soumya.mondal/Desktop/Projects/Arnie/arnie/models/Arnie/meshes/TH3_z.dae" scale="0.1 0.1 0.1"/>
      </geometry>
      <material name="shadow_thproximal_material">
        <color rgba="0.2 0.2 0.2 1.0"/>
      </material>
    </visual>
    <collision>
      <origin rpy="0 0 0" xyz="0 0 0.019"/>
      <geometry name="thproximal_collision_geom">
        <box size="0.008 0.008 0.020"/>
      </geometry>
    </collision>
  </link>
  <joint name="THJ4" type="revolute">
    <parent link="thbase"/>
    <child link="thproximal"/>
    <origin rpy="0 0 0" xyz="0 0 0"/>
    <axis xyz="1.0 0 0"/>
    <limit effort="100" lower="0" upper="1.309" velocity="1.0"/>
    <dynamics damping="50.5"/>
  </joint>
  <link name="thhub">
    <inertial>
      <mass value="0.002"/>
      <origin rpy="0 0 0" xyz="0 0 0"/>
      <inertia ixx="0.1" ixy="0.0" ixz="0.0" iyy="0.1" iyz="0.0" izz="0.1"/>
    </inertial>
    <visual>
      <origin rpy="0 0 0" xyz="0 0 0"/>
      <geometry name="thhub_visual">
        <box size="0.001 0.001 0.001"/>
      </geometry>
      <material name="shadow_thhub_material">
        <color rgba="0.7 0.7 0.7 1.0"/>
      </material>
    </visual>
    <collision>
      <origin rpy="0 0 0 " xyz="0 0 0"/>
      <geometry name="thhub_collision_geom">
        <box size="0.001 0.001 0.001"/>
      </geometry>
    </collision>
  </link>
  <joint name="THJ3" type="revolute">
    <parent link="thproximal"/>
    <child link="thhub"/>
    <origin rpy="0 0 0" xyz="0 0 0.038"/>
    <axis xyz="1 0 0"/>
    <limit effort="100" lower="-0.2618" upper="0.2618" velocity="1.0"/>
    <dynamics damping="50.5"/>
  </joint>
  <link name="thmiddle">
    <inertial>
      <mass value="0.016"/>
      <origin rpy="0 0 0" xyz="0 0 0.016"/>
      <inertia ixx="0.1" ixy="0.0" ixz="0.0" iyy="0.1" iyz="0.0" izz="0.1"/>
    </inertial>
    <visual>
      <origin rpy="0 0 0" xyz="0 0 0"/>
      <geometry name="thmiddle_visual">
        <mesh filename="/home/soumya.mondal/Desktop/Projects/Arnie/arnie/models/Arnie/meshes/TH2_z.dae" scale="0.1 0.1 0.1"/>
      </geometry>
      <material name="shadow_thmiddle_material">
        <color rgba="0.2 0.2 0.2 1.0"/>
      </material>
    </visual>
    <collision>
      <origin rpy="0 0 0 " xyz="0 0 0.016"/>
      <geometry name="thmiddle_collision_geom">
        <box size="0.008 0.008 0.015"/>
      </geometry>
    </collision>
  </link>
  <joint name="THJ2" type="revolute">
    <parent link="thhub"/>
    <child link="thmiddle"/>
    <origin rpy="0 0 0" xyz="0 0 0"/>
    <axis xyz="0 -1 0"/>
    <limit effort="100" lower="-0.5237" upper="0.5237" velocity="1.0"/>
    <dynamics damping="50.5"/>
  </joint>
  <link name="thdistal">
    <inertial>
      <mass value="0.016"/>
      <origin rpy="0 0 0" xyz="0 0 0.01375"/>
      <inertia ixx="0.1" ixy="0.0" ixz="0.0" iyy="0.1" iyz="0.0" izz="0.1"/>
    </inertial>
    <visual>
      <origin rpy="0 0 0" xyz="0 0.002 0.0025"/>
      <geometry name="thdistal_visual">
        <mesh filename="/home/soumya.mondal/Desktop/Projects/Arnie/arnie/models/Arnie/meshes/distal_ellipsoid.dae" scale="0.1 0.1 0.1"/>
      </geometry>
      <material name="shadow_thmiddle_material">
        <color rgba="0.2 0.2 0.2 1.0"/>
      </material>
    </visual>
    <collision>
      <origin rpy="0 0 0 " xyz="0 0.002 0.0025"/>
      <geometry name="thmiddle_collision_geom">
        <mesh filename="/home/soumya.mondal/Desktop/Projects/Arnie/arnie/models/Arnie/meshes/distal_ellipsoid.dae" scale="0.1 0.1 0.1"/>
      </geometry>
    </collision>
  </link>
  <joint name="THJ1" type="revolute">
    <parent link="thmiddle"/>
    <child link="thdistal"/>
    <origin rpy="0 0 -1.570796327" xyz="0 0 0.032"/>
    <axis xyz="1 0 0"/>
    <limit effort="100" lower="0" upper="1.571" velocity="1.0"/>
    <dynamics damping="50.5"/>
  </joint>
  <link name="thtip">
    <inertial>
      <mass value="0.001"/>
      <inertia ixx="0.0" ixy="0.0" ixz="0.0" iyy="0.0" iyz="0.0" izz="0.0"/>
    </inertial>
  </link>
  <joint name="thtip" type="fixed">
    <parent link="thdistal"/>
    <child link="thtip"/>
    <origin rpy="0 0 0" xyz="0 0 0.0275"/>
  </joint>
  <link name="right_base">
    <inertial>
      <origin rpy="0 0 0" xyz="0.00153097191906452 0.00152031034664837 0.0524230280849149"/>
      <mass value="1.33110743457779"/>
      <inertia ixx="0.00695879790529406" ixy="9.99328685258342E-05" ixz="7.99577031212481E-05" iyy="0.00695365531716522" iyz="7.90796997368543E-05" izz="0.00729823323321907"/>
    </inertial>
    <visual>
      <origin rpy="0 0 0" xyz="0 0 0"/>
      <geometry>
        <mesh filename="/home/soumya.mondal/Desktop/IsaacGymEnvs/assets/urdf/arnie/meshes/visual/right_base.obj"/>
      </geometry>
      <material name="">
        <color rgba="0.796078431372549 0.823529411764706 0.937254901960784 1"/>
      </material>
    </visual>
    <collision>
      <origin rpy="0 0 0" xyz="0 0 0"/>
      <geometry>
        <mesh filename="/home/soumya.mondal/Desktop/IsaacGymEnvs/assets/urdf/arnie/meshes/collision/right_base.stl"/>
      </geometry>
    </collision>
  </link>
  <link name="right_link_1">
    <inertial>
      <origin rpy="0 0 0" xyz="5.5234067920554E-05  -0.0254878204920178 0.0355441421264809"/>
      <mass value="1.09025546409174"/>
      <inertia ixx="0.00585031196428369" ixy="1.4630349447555E-07" ixz="1.35351687162397E-06" iyy="0.00645496952227061" iyz="-0.00104800484741808" izz="0.00459531291521244"/>
    </inertial>
    <visual>
      <origin rpy="3.1415926531795866 0 0" xyz="0 0 0"/>
      <geometry>
        <mesh filename="/home/soumya.mondal/Desktop/IsaacGymEnvs/assets/urdf/arnie/meshes/visual/right_link_1.obj"/>
      </geometry>
      <material name="">
        <color rgba="0.796078431372549 0.823529411764706 0.937254901960784 1"/>
      </material>
    </visual>
    <collision>
      <origin rpy="3.1415926531795866 0 0" xyz="0 0 0"/>
      <geometry>
        <mesh filename="/home/soumya.mondal/Desktop/IsaacGymEnvs/assets/urdf/arnie/meshes/collision/right_link_1.stl"/>
      </geometry>
    </collision>
  </link>
  <joint name="right_joint_1" type="revolute">
    <origin rpy="-3.1415926535795866 0.0 -0.0" xyz="0.0 -2.9150689157e-12 0.2856"/>
    <parent link="right_base"/>
    <child link="right_link_1"/>
    <axis xyz="0 0 1"/>
    <limit effort="235" lower="-3.12" upper="3.12" velocity="2.618"/>
  </joint>
  <link name="right_link_2">
    <inertial>
      <origin rpy="0 0 0" xyz="-3.62724763868157E-06 -0.0292741005087307 -0.041280769252073"/>
      <mass value="1.09515454908799"/>
      <inertia ixx="0.00575817488413533" ixy="4.92454490330888E-07" ixz="-5.75758988171004E-07" iyy="0.00452592941277235" iyz="0.00135206824645357" izz="0.0058904584276842"/>
    </inertial>
    <visual>
      <origin rpy="0 0 0" xyz="0 0 0"/>
      <geometry>
        <mesh filename="/home/soumya.mondal/Desktop/IsaacGymEnvs/assets/urdf/arnie/meshes/visual/right_link_2.obj"/>
      </geometry>
      <material name="">
        <color rgba="0.980392156862745 0.980392156862745 0.470588235294118 1"/>
      </material>
    </visual>
    <collision>
      <origin rpy="0 0 0" xyz="0 0 0"/>
      <geometry>
        <mesh filename="/home/soumya.mondal/Desktop/IsaacGymEnvs/assets/urdf/arnie/meshes/collision/right_link_2.stl"/>
      </geometry>
    </collision>
  </link>
  <joint name="right_joint_2" type="revolute">
    <origin rpy="1.57079632679 -0.0 0.0" xyz="0.0 -0.0 0.0"/>
    <parent link="right_link_1"/>
    <child link="right_link_2"/>
    <axis xyz="0 0 1"/>
    <limit effort="235" lower="-1.57" upper="1.57" velocity="2.618"/>
  </joint>
  <link name="right_link_3">
    <inertial>
      <origin rpy="0 3.1415926531795866 3.1415926531795866" xyz="0.0114318213510691 -0.0101707598694861 0.15131695375217"/>
      <mass value="2.01686690128149"/>
      <inertia ixx="0.0362470020041464" ixy="-0.00099203786071914" ixz="-0.00494440140493448" iyy="0.0374857206758098" iyz="-0.00313859974095155" izz="0.00905850119342719"/>
    </inertial>
    <visual>
      <origin rpy="3.1415926531795866 0 0" xyz="0 0 0"/>
      <geometry>
        <mesh filename="/home/soumya.mondal/Desktop/IsaacGymEnvs/assets/urdf/arnie/meshes/visual/right_link_3.obj"/>
      </geometry>
      <material name="">
        <color rgba="0.898039215686275 0.917647058823529 0.929411764705882 1"/>
      </material>
    </visual>
    <collision>
      <origin rpy="3.1415926531795866 0 0" xyz="0 0 0"/>
      <geometry>
        <mesh filename="/home/soumya.mondal/Desktop/IsaacGymEnvs/assets/urdf/arnie/meshes/collision/right_link_3.stl"/>
      </geometry>
    </collision>
  </link>
  <joint name="right_joint_3" type="revolute">
    <origin rpy="-1.57079632679 0.0 0.0" xyz="0.0 -0.4586 -2.24557565126e-12"/>
    <parent link="right_link_2"/>
    <child link="right_link_3"/>
    <axis xyz="0 0 1"/>
    <limit effort="111" lower="-3.12" upper="3.12" velocity="3.1416"/>
  </joint>
  <link name="right_link_4">
    <inertial>
      <origin rpy="0 0 0" xyz="-0.0240716370537192 -0.0235631728011761 -0.0366858174253844"/>
      <mass value="0.849743349506889"/>
      <inertia ixx="0.00313444335639628" ixy="-0.000681243351041131" ixz="0.000725380047812207" iyy="0.00333717642442852" iyz="0.000771057559109157" izz="0.0034847726349841"/>
    </inertial>
    <visual>
      <origin rpy="0 0 0" xyz="0 0 0"/>
      <geometry>
        <mesh filename="/home/soumya.mondal/Desktop/IsaacGymEnvs/assets/urdf/arnie/meshes/visual/right_link_4.obj"/>
      </geometry>
      <material name="">
        <color rgba="0.898039215686275 0.917647058823529 0.929411764705882 1"/>
      </material>
    </visual>
    <collision>
      <origin rpy="0 0 0" xyz="0 0 0"/>
      <geometry>
        <mesh filename="/home/soumya.mondal/Desktop/IsaacGymEnvs/assets/urdf/arnie/meshes/collision/right_link_4.stl"/>
      </geometry>
    </collision>
  </link>
  <joint name="right_joint_4" type="revolute">
    <origin rpy="1.57079632679 -0.0 0.0" xyz="0.065 -0.0 0.0"/>
    <parent link="right_link_3"/>
    <child link="right_link_4"/>
    <axis xyz="0 0 1"/>
    <limit effort="111" lower="0" upper="3.05" velocity="3.1416"/>
  </joint>
  <link name="right_link_5">
    <inertial>
      <origin rpy="0 3.1415926531795866 3.1415926531795866" xyz="-0.00867148011164554 0.0383499684802812 0.188626"/>
      <mass value="1.20580396965245"/>
      <inertia ixx="0.0218436427570802" ixy="-0.000309747330693722" ixz="0.00089039094846826" iyy="0.0205896836785318" iyz="0.00493573923914426" izz="0.00372270106038425"/>
    </inertial>
    <visual>
      <origin rpy="3.1415926531795866 0 0" xyz="0 0 -0.02162"/>
      <geometry>
        <mesh filename="/home/soumya.mondal/Desktop/IsaacGymEnvs/assets/urdf/arnie/meshes/visual/right_link_5.obj"/>
      </geometry>
      <material name="">
        <color rgba="0.898039215686275 0.917647058823529 0.929411764705882 1"/>
      </material>
    </visual>
    <collision>
      <origin rpy="3.1415926531795866 0 0" xyz="0 0 -0.02162"/>
      <geometry>
        <mesh filename="/home/soumya.mondal/Desktop/IsaacGymEnvs/assets/urdf/arnie/meshes/collision/right_link_5.stl"/>
      </geometry>
    </collision>
  </link>
  <joint name="right_joint_5" type="revolute">
    <origin rpy="-1.57079632679 0.0 0.0" xyz="-0.0528 -0.4554 -2.22990656691e-12"/>
    <parent link="right_link_4"/>
    <child link="right_link_5"/>
    <axis xyz="0 0 1"/>
    <limit effort="54" lower="-3.12" upper="3.12" velocity="2.618"/>
  </joint>
  <link name="right_link_6">
    <inertial>
      <origin rpy="0 3.1415926531795866 3.1415926531795866" xyz="0.045897226241036 0.00848579821002571 -0.0078257811617596"/>
      <mass value="0.847157564562275"/>
      <inertia ixx="0.00286926864109097" ixy="-0.000341664135091818" ixz="-0.000318082297486923" iyy="0.0043294660443987" iyz="-5.82962380662208E-05" izz="0.00437292566725527"/>
    </inertial>
    <visual>
      <origin rpy="3.1415926531795866 0 3.14159265359" xyz="0 0 0"/>
      <geometry>
        <mesh filename="/home/soumya.mondal/Desktop/IsaacGymEnvs/assets/urdf/arnie/meshes/visual/right_link_6.obj"/>
      </geometry>
      <material name="">
        <color rgba="0.980392156862745 0.980392156862745 0.470588235294118 1"/>
      </material>
    </visual>
    <collision>
      <origin rpy="3.1415926531795866 0 3.14159265359" xyz="0 0 0"/>
      <geometry>
        <mesh filename="/home/soumya.mondal/Desktop/IsaacGymEnvs/assets/urdf/arnie/meshes/collision/right_link_6.stl"/>
      </geometry>
    </collision>
  </link>
  <joint name="right_joint_6" type="revolute">
    <origin rpy="1.57079632679 -1.0206823934513925e-11 -3.141592653589793" xyz="-0.0122 0.0 0.0"/>
    <parent link="right_link_5"/>
    <child link="right_link_6"/>
    <axis xyz="0 0 1"/>
    <limit effort="54" lower="-3.12" upper="0.52" velocity="2.618"/>
  </joint>
  <link name="right_link_7">
    <inertial>
      <origin rpy="0 0 0" xyz="0.00117005127509708 5.03191940906655E-06 0.0151381784822231"/>
      <mass value="0.233956150459573"/>
      <inertia ixx="0.000142027360977168" ixy="1.76426389345981E-08" ixz="2.14635741626268E-07" iyy="0.000134421724783865" iyz="-1.29988689037464E-09" izz="0.000240242798572463"/>
    </inertial>
    <visual>
      <origin rpy="0 0 0" xyz="0 0 0"/>
      <geometry>
        <mesh filename="/home/soumya.mondal/Desktop/IsaacGymEnvs/assets/urdf/arnie/meshes/visual/right_link_7.obj"/>
      </geometry>
      <material name="">
        <color rgba="0.898039215686275 0.917647058823529 0.929411764705882 1"/>
      </material>
    </visual>
    <collision>
      <origin rpy="0 0 0" xyz="0 0 0"/>
      <geometry>
        <mesh filename="/home/soumya.mondal/Desktop/IsaacGymEnvs/assets/urdf/arnie/meshes/collision/right_link_7.stl"/>
      </geometry>
    </collision>
  </link>
  <joint name="right_joint_7" type="revolute">
    <origin rpy="-1.57079632679 0.0 0.0" xyz="0.087 -0.1169 -5.72411237751e-13"/>
    <parent link="right_link_6"/>
    <child link="right_link_7"/>
    <axis xyz="0 0 1"/>
    <limit effort="54" lower="-3.12" upper="3.12" velocity="3.1416"/>
  </joint>
  <link name="right_link_7_fake">
  </link>
  <joint name="right_link_7_to_right_link_7_fake" type="fixed">
    <parent link="right_link_7" />
    <child link="right_link_7_fake" />
    <origin rpy="3.1415926 0 0" xyz="0 0 0" />
  </joint>
  <link name="forearm">
    <inertial>
      <origin rpy="0 0 0" xyz="0 0 0.09"/>
      <!-- <mass value="3.0"/> -->
      <mass value="3.0"/>

      <inertia ixx="1.0" ixy="0.0" ixz="0.0" iyy="1.0" iyz="0.0" izz="1.0"/>
    </inertial>
    <visual>
      <origin rpy="0 0 0" xyz="0 0 0"/>
      <geometry name="shadow_forearm_geom">
        <mesh filename="/home/soumya.mondal/Desktop/Projects/Arnie/arnie/models/Arnie/meshes/forearm.dae" scale="0.1 0.1 0.1"/>
      </geometry>
      <material name="Grey"/>
    </visual>
    <collision>
      <origin rpy="0 0 0" xyz="0 0 0.09"/>
      <geometry name="shadow_forearm_collision">
        <cylinder length="0.180" radius="0.06"/>
      </geometry>
    </collision>
  </link>
  <joint name="forearm" type="fixed">
    <parent link="right_link_7_fake" />
    <child link="forearm" />
    <!-- <origin rpy="-1.57 0 0" xyz="0 0 -0.05" /> -->
      <origin rpy="0 0 0" xyz="0 0 0.05" />
  </joint>
  <link name="wrist">
    <inertial>
      <origin rpy="0 0 0" xyz="0 0.0 0.0"/>
      <mass value="0.1"/>
      <!-- <inertia ixx="0.120" ixy="0.0" ixz="0.0" iyy="0.148" iyz="0.0" izz="0.0438"/> -->
      <inertia ixx="0.120" ixy="0.0" ixz="0.0" iyy="0.148" iyz="0.0" izz="0.0438"/>

    </inertial>
    <visual>
      <origin rpy="0 0 0" xyz="0 0 0"/>
      <geometry name="wrist_visual">
        <mesh filename="/home/soumya.mondal/Desktop/Projects/Arnie/arnie/models/Arnie/meshes/wrist.dae" scale="0.1 0.1 0.1"/>
      </geometry>
      <material name="LightGrey"/>
    </visual>
    <collision>
      <origin rpy="0 0 0" xyz="0 0 0"/>
      <geometry name="wrist_collision_geom">
        <box size="0.02 0.02 0.02"/>
      </geometry>
    </collision>
  </link>
  <joint name="WRJ2" type="revolute">
    <parent link="forearm"/>
    <child link="wrist"/>
      <!-- <origin rpy="0 0 -3.14" xyz="0 -0.010  0.213"/> -->
    <origin rpy="0 0 0" xyz="0 -0.010 0.213"/>
    <axis xyz="0 1 0"/>
    <limit effort="5" lower="-0.52359877559829882" upper="0.17453292519943295" velocity="1.0"/>
    <dynamics damping="100.5"/>
  </joint>
  <link name="palm">
    <inertial>
      <origin rpy="0 0 0" xyz="0 0 0.035"/>
      <mass value="0.3"/>
      <inertia ixx="0.5" ixy="0.0" ixz="0.0" iyy="0.5" iyz="0.0" izz="0.3"/>
    </inertial>
    <visual>
      <origin rpy="0 0 0" xyz="0 0 0"/>
      <geometry name="palm_visual">
        <mesh filename="/home/soumya.mondal/Desktop/Projects/Arnie/arnie/models/Arnie/meshes/palm.dae" scale="0.1 0.1 0.1"/>
      </geometry>
      <material name="Grey"/>
    </visual>
    <collision>
      <origin rpy="0 0 0" xyz="0.005 0 0.035"/>
      <geometry name="palm_collision_geom">
        <box size="0.05 0.02 0.07"/>
      </geometry>
    </collision>
  </link>
  <joint name="WRJ1" type="revolute">
    <parent link="wrist"/>
    <child link="palm"/>
    <origin rpy="0 0 0" xyz="0 0 0.034"/>
    <axis xyz="1 0 0"/>
    <limit effort="5" lower="-0.78539816339744828" upper="0.6108652381980153" velocity="1.0"/>
    <dynamics damping="100.5"/>
  </joint>
  <link name="ffknuckle">
    <inertial>
      <origin rpy="0 0 0" xyz="0 0 0"/>
      <mass value="0.008"/>
      <inertia ixx="0.0" ixy="0.0" ixz="0.0" iyy="0.1" iyz="0.0" izz="0.0"/>
    </inertial>
    <visual>
      <origin rpy="0 0 0" xyz="0 0 0.0005"/>
      <geometry name="knuckle_visual">
        <mesh filename="/home/soumya.mondal/Desktop/Projects/Arnie/arnie/models/Arnie/meshes/knuckle.dae" scale="0.1 0.1 0.1"/>
      </geometry>
      <material name="LightGrey"/>
    </visual>
    <collision>
      <origin rpy="0 0 0" xyz="0 0 0"/>
      <geometry name="knuckle_collision_geom">
        <box size="0.005 0.005 0.005"/>
      </geometry>
    </collision>
  </link>
  <joint name="FFJ4" type="revolute">
    <parent link="palm"/>
    <child link="ffknuckle"/>
    <origin rpy="0 0 0" xyz="0.033 0 0.095"/>
    <axis xyz="0 -1 0"/>
    <limit effort="100" lower="-0.43633231299858238" upper="0.43633231299858238" velocity="1.0"/>
    <dynamics damping="50.5"/>
  </joint>
  <link name="ffproximal">
    <inertial>
      <mass value="0.014"/>
      <origin xyz="0 0 0.0225"/>
      <inertia ixx="0.1" ixy="0.0" ixz="0.0" iyy="0.1" iyz="0.0" izz="0.0"/>
    </inertial>
    <visual>
      <origin rpy="0 0 0" xyz="0 0 0"/>
      <geometry name="proximal_visual">
        <mesh filename="/home/soumya.mondal/Desktop/Projects/Arnie/arnie/models/Arnie/meshes/F3.dae" scale="0.1 0.1 0.1"/>
      </geometry>
      <material name="Grey"/>
    </visual>
    <collision>
      <origin rpy="0 0 0 " xyz="0 0 0.025"/>
      <geometry name="proximal_collision_geom">
        <box size="0.008 0.008 0.04"/>
      </geometry>
    </collision>
  </link>
  <joint name="FFJ3" type="revolute">
    <parent link="ffknuckle"/>
    <child link="ffproximal"/>
    <origin rpy="0 0 0" xyz="0 0 0"/>
    <axis xyz="1 0 0"/>
    <limit effort="100" lower="0" upper="1.57079632679" velocity="1.0"/>
    <dynamics damping="50.5"/>
  </joint>
  <link name="ffmiddle">
    <inertial>
      <origin rpy="0 0 0" xyz="0 0 0.0125"/>
      <mass value="0.012"/>
      <inertia ixx="0.1" ixy="0.0" ixz="0.0" iyy="0.1" iyz="0.0" izz="0.0"/>
    </inertial>
    <visual>
      <origin rpy="0 0 0" xyz="0 0 0"/>
      <geometry name="middle_visual">
        <mesh filename="/home/soumya.mondal/Desktop/Projects/Arnie/arnie/models/Arnie/meshes/F2.dae" scale="0.1 0.1 0.1"/>
      </geometry>
      <material name="Grey"/>
    </visual>
    <collision>
      <origin rpy="0 0 0" xyz="0 0 0.0125"/>
      <geometry name="middle_collision_geom">
        <box size="0.008 0.008 0.015"/>
      </geometry>
    </collision>
  </link>
  <joint name="FFJ2" type="revolute">
    <parent link="ffproximal"/>
    <child link="ffmiddle"/>
    <origin rpy="0 0 0" xyz="0 0 0.045"/>
    <axis xyz="1 0 0"/>
    <limit effort="100" lower="0" upper="1.57079632679" velocity="1.0"/>
    <dynamics damping="50.5"/>
  </joint>
  <link name="ffdistal">
    <inertial>
      <mass value="0.010"/>
      <origin xyz="0 0 0.013"/>
      <inertia ixx="0.1" ixy="0.0" ixz="0.0" iyy="0.1" iyz="0.0" izz="0.0"/>
    </inertial>
    <visual>
      <origin rpy="0 0 0" xyz="0 0 0"/>
      <geometry name="distal_visual">
        <mesh filename="/home/soumya.mondal/Desktop/Projects/Arnie/arnie/models/Arnie/meshes/distal_ellipsoid.dae" scale="0.1 0.1 0.1"/>
      </geometry>
      <material name="Grey"/>
    </visual>
    <collision>
      <origin rpy="0 0 0" xyz="0 0 0"/>
      <geometry name="distal_collision_geom">
        <mesh filename="/home/soumya.mondal/Desktop/Projects/Arnie/arnie/models/Arnie/meshes/distal_ellipsoid.dae" scale="0.1 0.1 0.1"/>
      </geometry>
    </collision>
  </link>
  <joint name="FFJ1" type="revolute">
    <parent link="ffmiddle"/>
    <child link="ffdistal"/>
    <origin rpy="0 0 0" xyz="0 0 0.025"/>
    <axis xyz="1 0 0"/>
    <limit effort="100" lower="0" upper="1.57079632679" velocity="1.0"/>
    <dynamics damping="50.5"/>
  </joint>
  <link name="fftip">
    <inertial>
      <mass value="0.001"/>
      <inertia ixx="0.0" ixy="0.0" ixz="0.0" iyy="0.0" iyz="0.0" izz="0.0"/>
    </inertial>
  </link>
  <joint name="FFtip" type="fixed">
    <parent link="ffdistal"/>
    <child link="fftip"/>
    <origin rpy="0 0 0" xyz="0 0 0.026"/>
  </joint>
  <link name="mfknuckle">
    <inertial>
      <origin rpy="0 0 0" xyz="0 0 0"/>
      <mass value="0.008"/>
      <inertia ixx="0.0" ixy="0.0" ixz="0.0" iyy="0.1" iyz="0.0" izz="0.0"/>
    </inertial>
    <visual>
      <origin rpy="0 0 0" xyz="0 0 0.0005"/>
      <geometry name="knuckle_visual">
        <mesh filename="/home/soumya.mondal/Desktop/Projects/Arnie/arnie/models/Arnie/meshes/knuckle.dae" scale="0.1 0.1 0.1"/>
      </geometry>
      <material name="LightGrey"/>
    </visual>
    <collision>
      <origin rpy="0 0 0" xyz="0 0 0"/>
      <geometry name="knuckle_collision_geom">
        <box size="0.005 0.005 0.005"/>
      </geometry>
    </collision>
  </link>
  <joint name="MFJ4" type="revolute">
    <parent link="palm"/>
    <child link="mfknuckle"/>
    <origin rpy="0 0 0" xyz="0.011 0 0.099"/>
    <axis xyz="0 -1 0"/>
    <limit effort="100" lower="-0.43633231299858238" upper="0.43633231299858238" velocity="1.0"/>
    <dynamics damping="50.5"/>
  </joint>
  <link name="mfproximal">
    <inertial>
      <mass value="0.014"/>
      <origin xyz="0 0 0.0225"/>
      <inertia ixx="0.1" ixy="0.0" ixz="0.0" iyy="0.1" iyz="0.0" izz="0.0"/>
    </inertial>
    <visual>
      <origin rpy="0 0 0" xyz="0 0 0"/>
      <geometry name="proximal_visual">
        <mesh filename="/home/soumya.mondal/Desktop/Projects/Arnie/arnie/models/Arnie/meshes/F3.dae" scale="0.1 0.1 0.1"/>
      </geometry>
      <material name="Grey"/>
    </visual>
    <collision>
      <origin rpy="0 0 0 " xyz="0 0 0.025"/>
      <geometry name="proximal_collision_geom">
        <box size="0.008 0.008 0.04"/>
      </geometry>
    </collision>
  </link>
  <joint name="MFJ3" type="revolute">
    <parent link="mfknuckle"/>
    <child link="mfproximal"/>
    <origin rpy="0 0 0" xyz="0 0 0"/>
    <axis xyz="1 0 0"/>
    <limit effort="100" lower="0" upper="1.57079632679" velocity="1.0"/>
    <dynamics damping="50.5"/>
  </joint>
  <link name="mfmiddle">
    <inertial>
      <origin rpy="0 0 0" xyz="0 0 0.0125"/>
      <mass value="0.012"/>
      <inertia ixx="0.1" ixy="0.0" ixz="0.0" iyy="0.1" iyz="0.0" izz="0.0"/>
    </inertial>
    <visual>
      <origin rpy="0 0 0" xyz="0 0 0"/>
      <geometry name="middle_visual">
        <mesh filename="/home/soumya.mondal/Desktop/Projects/Arnie/arnie/models/Arnie/meshes/F2.dae" scale="0.1 0.1 0.1"/>
      </geometry>
      <material name="Grey"/>
    </visual>
    <collision>
      <origin rpy="0 0 0" xyz="0 0 0.0125"/>
      <geometry name="middle_collision_geom">
        <box size="0.008 0.008 0.015"/>
      </geometry>
    </collision>
  </link>
  <joint name="MFJ2" type="revolute">
    <parent link="mfproximal"/>
    <child link="mfmiddle"/>
    <origin rpy="0 0 0" xyz="0 0 0.045"/>
    <axis xyz="1 0 0"/>
    <limit effort="100" lower="0" upper="1.57079632679" velocity="1.0"/>
    <dynamics damping="50.5"/>
  </joint>
  <link name="mfdistal">
    <inertial>
      <mass value="0.010"/>
      <origin xyz="0 0 0.013"/>
      <inertia ixx="0.1" ixy="0.0" ixz="0.0" iyy="0.1" iyz="0.0" izz="0.0"/>
    </inertial>
    <visual>
      <origin rpy="0 0 0" xyz="0 0 0"/>
      <geometry name="distal_visual">
        <mesh filename="/home/soumya.mondal/Desktop/Projects/Arnie/arnie/models/Arnie/meshes/F1.dae" scale="0.1 0.1 0.1"/>
      </geometry>
      <material name="Grey"/>
    </visual>
    <collision>
      <origin rpy="0 0 0" xyz="0 0 0"/>
      <geometry name="distal_collision_geom">
        <mesh filename="/home/soumya.mondal/Desktop/Projects/Arnie/arnie/models/Arnie/meshes/F1.dae" scale="0.1 0.1 0.1"/>
      </geometry>
    </collision>
  </link>
  <joint name="MFJ1" type="revolute">
    <parent link="mfmiddle"/>
    <child link="mfdistal"/>
    <origin rpy="0 0 0" xyz="0 0 0.025"/>
    <axis xyz="1 0 0"/>
    <limit effort="100" lower="0" upper="1.57079632679" velocity="1.0"/>
    <dynamics damping="50.5"/>
  </joint>
  <link name="mftip">
    <inertial>
      <mass value="0.001"/>
      <inertia ixx="0.0" ixy="0.0" ixz="0.0" iyy="0.0" iyz="0.0" izz="0.0"/>
    </inertial>
  </link>
  <joint name="MFtip" type="fixed">
    <parent link="mfdistal"/>
    <child link="mftip"/>
    <origin rpy="0 0 0" xyz="0 0 0.026"/>
  </joint>
  <link name="rfknuckle">
    <inertial>
      <origin rpy="0 0 0" xyz="0 0 0"/>
      <mass value="0.008"/>
      <inertia ixx="0.0" ixy="0.0" ixz="0.0" iyy="0.1" iyz="0.0" izz="0.0"/>
    </inertial>
    <visual>
      <origin rpy="0 0 0" xyz="0 0 0.0005"/>
      <geometry name="knuckle_visual">
        <mesh filename="/home/soumya.mondal/Desktop/Projects/Arnie/arnie/models/Arnie/meshes/knuckle.dae" scale="0.1 0.1 0.1"/>
      </geometry>
      <material name="LightGrey"/>
    </visual>
    <collision>
      <origin rpy="0 0 0" xyz="0 0 0"/>
      <geometry name="knuckle_collision_geom">
        <box size="0.005 0.005 0.005"/>
      </geometry>
    </collision>
  </link>
  <joint name="RFJ4" type="revolute">
    <parent link="palm"/>
    <child link="rfknuckle"/>
    <origin rpy="0 0 0" xyz="-0.011 0 0.095"/>
    <axis xyz="0 1 0"/>
    <limit effort="100" lower="-0.43633231299858238" upper="0.43633231299858238" velocity="1.0"/>
    <dynamics damping="50.5"/>
  </joint>
  <link name="rfproximal">
    <inertial>
      <mass value="0.014"/>
      <origin xyz="0 0 0.0225"/>
      <inertia ixx="0.1" ixy="0.0" ixz="0.0" iyy="0.1" iyz="0.0" izz="0.0"/>
    </inertial>
    <visual>
      <origin rpy="0 0 0" xyz="0 0 0"/>
      <geometry name="proximal_visual">
        <mesh filename="/home/soumya.mondal/Desktop/Projects/Arnie/arnie/models/Arnie/meshes/F3.dae" scale="0.1 0.1 0.1"/>
      </geometry>
      <material name="Grey"/>
    </visual>
    <collision>
      <origin rpy="0 0 0 " xyz="0 0 0.025"/>
      <geometry name="proximal_collision_geom">
        <box size="0.008 0.008 0.04"/>
      </geometry>
    </collision>
  </link>
  <joint name="RFJ3" type="revolute">
    <parent link="rfknuckle"/>
    <child link="rfproximal"/>
    <origin rpy="0 0 0" xyz="0 0 0"/>
    <axis xyz="1 0 0"/>
    <limit effort="100" lower="0" upper="1.57079632679" velocity="1.0"/>
    <dynamics damping="50.5"/>
  </joint>
  <link name="rfmiddle">
    <inertial>
      <origin rpy="0 0 0" xyz="0 0 0.0125"/>
      <mass value="0.012"/>
      <inertia ixx="0.1" ixy="0.0" ixz="0.0" iyy="0.1" iyz="0.0" izz="0.0"/>
    </inertial>
    <visual>
      <origin rpy="0 0 0" xyz="0 0 0"/>
      <geometry name="middle_visual">
        <mesh filename="/home/soumya.mondal/Desktop/Projects/Arnie/arnie/models/Arnie/meshes/F2.dae" scale="0.1 0.1 0.1"/>
      </geometry>
      <material name="Grey"/>
    </visual>
    <collision>
      <origin rpy="0 0 0" xyz="0 0 0.0125"/>
      <geometry name="middle_collision_geom">
        <box size="0.008 0.008 0.015"/>
      </geometry>
    </collision>
  </link>
  <joint name="RFJ2" type="revolute">
    <parent link="rfproximal"/>
    <child link="rfmiddle"/>
    <origin rpy="0 0 0" xyz="0 0 0.045"/>
    <axis xyz="1 0 0"/>
    <limit effort="100" lower="0" upper="1.57079632679" velocity="1.0"/>
    <dynamics damping="50.5"/>
  </joint>
  <link name="rfdistal">
    <inertial>
      <mass value="0.010"/>
      <origin xyz="0 0 0.013"/>
      <inertia ixx="0.1" ixy="0.0" ixz="0.0" iyy="0.1" iyz="0.0" izz="0.0"/>
    </inertial>
    <visual>
      <origin rpy="0 0 0" xyz="0 0 0"/>
      <geometry name="distal_visual">
        <mesh filename="/home/soumya.mondal/Desktop/Projects/Arnie/arnie/models/Arnie/meshes/distal_ellipsoid.dae" scale="0.1 0.1 0.1"/>
      </geometry>
      <material name="Grey"/>
    </visual>
    <collision>
      <origin rpy="0 0 0" xyz="0 0 0"/>
      <geometry name="distal_collision_geom">
        <mesh filename="/home/soumya.mondal/Desktop/Projects/Arnie/arnie/models/Arnie/meshes/distal_ellipsoid.dae" scale="0.1 0.1 0.1"/>
      </geometry>
    </collision>
  </link>
  <joint name="RFJ1" type="revolute">
    <parent link="rfmiddle"/>
    <child link="rfdistal"/>
    <origin rpy="0 0 0" xyz="0 0 0.025"/>
    <axis xyz="1 0 0"/>
    <limit effort="100" lower="0" upper="1.57079632679" velocity="1.0"/>
    <dynamics damping="50.5"/>
  </joint>
  <link name="rftip">
    <inertial>
      <mass value="0.001"/>
      <inertia ixx="0.0" ixy="0.0" ixz="0.0" iyy="0.0" iyz="0.0" izz="0.0"/>
    </inertial>
  </link>
  <joint name="RFtip" type="fixed">
    <parent link="rfdistal"/>
    <child link="rftip"/>
    <origin rpy="0 0 0" xyz="0 0 0.026"/>
  </joint>
  <link name="lfmetacarpal">
    <inertial>
      <origin rpy="0 0 0" xyz="0 0 0.04"/>
      <mass value="0.075"/>
      <inertia ixx="0.1" ixy="0.0" ixz="0.0" iyy="0.1" iyz="0.0" izz="0.1"/>
    </inertial>
    <visual>
      <origin rpy="0 0 0" xyz="0 0 0"/>
      <geometry name="lfmetacarpal_visual">
        <mesh filename="/home/soumya.mondal/Desktop/Projects/Arnie/arnie/models/Arnie/meshes/lfmetacarpal.dae" scale="0.1 0.1 0.1"/>
      </geometry>
      <material name="Grey"/>
    </visual>
    <collision>
      <origin rpy="0 0 0" xyz="0 0 0.04"/>
      <geometry name="lfmetacarpal_collision_geom">
        <box size="0.008 0.008 0.03"/>
      </geometry>
    </collision>
  </link>
  <joint name="LFJ5" type="revolute">
    <parent link="palm"/>
    <child link="lfmetacarpal"/>
    <origin rpy="0 0 0" xyz="-0.033 0 0.02071"/>
    <axis xyz="0.573576436 0 0.819152044"/>
    <limit effort="100" lower="0" upper="0.69813170079773179" velocity="1.0"/>
    <dynamics damping="50.5"/>
  </joint>
  <link name="lfknuckle">
    <inertial>
      <origin rpy="0 0 0" xyz="0 0 0.06579"/>
      <mass value="0.008"/>
      <inertia ixx="0.1" ixy="0.0" ixz="0.0" iyy="0.1" iyz="0.0" izz="0.1"/>
    </inertial>
    <visual>
      <origin rpy="0 0 0" xyz="0 0 0"/>
      <geometry name="knuckle_visual">
        <mesh filename="/home/soumya.mondal/Desktop/Projects/Arnie/arnie/models/Arnie/meshes/knuckle.dae" scale="0.1 0.1 0.1"/>
      </geometry>
      <material name="LightGrey"/>
    </visual>
    <collision>
      <origin rpy="0 0 0" xyz="0 0 0"/>
      <geometry name="knuckle_collision_geom">
        <box size="0.005 0.005 0.005"/>
      </geometry>
    </collision>
  </link>
  <joint name="LFJ4" type="revolute">
    <parent link="lfmetacarpal"/>
    <child link="lfknuckle"/>
    <origin rpy="0 0 0" xyz="0 0 0.06579"/>
    <axis xyz="0 1 0"/>
    <limit effort="100" lower="-0.43633231299858238" upper="0.43633231299858238" velocity="1.0"/>
    <dynamics damping="50.5"/>
  </joint>
  <link name="lfproximal">
    <inertial>
      <mass value="0.014"/>
      <origin xyz="0 0 0.0225"/>
      <inertia ixx="0.1" ixy="0.0" ixz="0.0" iyy="0.1" iyz="0.0" izz="0.0"/>
    </inertial>
    <visual>
      <origin rpy="0 0 0" xyz="0 0 0"/>
      <geometry name="proximal_visual">
        <mesh filename="/home/soumya.mondal/Desktop/Projects/Arnie/arnie/models/Arnie/meshes/F3.dae" scale="0.1 0.1 0.1"/>
      </geometry>
      <material name="Grey"/>
    </visual>
    <collision>
      <origin rpy="0 0 0 " xyz="0 0 0.025"/>
      <geometry name="proximal_collision_geom">
        <box size="0.008 0.008 0.04"/>
      </geometry>
    </collision>
  </link>
  <joint name="LFJ3" type="revolute">
    <parent link="lfknuckle"/>
    <child link="lfproximal"/>
    <origin rpy="0 0 0" xyz="0 0 0"/>
    <axis xyz="1 0 0"/>
    <limit effort="100" lower="0" upper="1.57079632679" velocity="1.0"/>
    <dynamics damping="50.5"/>
  </joint>
  <link name="lfmiddle">
    <inertial>
      <origin rpy="0 0 0" xyz="0 0 0.0125"/>
      <mass value="0.012"/>
      <inertia ixx="0.1" ixy="0.0" ixz="0.0" iyy="0.1" iyz="0.0" izz="0.0"/>
    </inertial>
    <visual>
      <origin rpy="0 0 0" xyz="0 0 0"/>
      <geometry name="middle_visual">
        <mesh filename="/home/soumya.mondal/Desktop/Projects/Arnie/arnie/models/Arnie/meshes/F2.dae" scale="0.1 0.1 0.1"/>
      </geometry>
      <material name="Grey"/>
    </visual>
    <collision>
      <origin rpy="0 0 0" xyz="0 0 0.0125"/>
      <geometry name="middle_collision_geom">
        <box size="0.008 0.008 0.015"/>
      </geometry>
    </collision>
  </link>
  <joint name="LFJ2" type="revolute">
    <parent link="lfproximal"/>
    <child link="lfmiddle"/>
    <origin rpy="0 0 0" xyz="0 0 0.045"/>
    <axis xyz="1 0 0"/>
    <limit effort="100" lower="0" upper="1.57079632679" velocity="1.0"/>
    <dynamics damping="50.5"/>
  </joint>
  <link name="lfdistal">
    <inertial>
      <mass value="0.010"/>
      <origin xyz="0 0 0.013"/>
      <inertia ixx="0.1" ixy="0.0" ixz="0.0" iyy="0.1" iyz="0.0" izz="0.0"/>
    </inertial>
    <visual>
      <origin rpy="0 0 0" xyz="0 0 0"/>
      <geometry name="distal_visual">
        <mesh filename="/home/soumya.mondal/Desktop/Projects/Arnie/arnie/models/Arnie/meshes/F1.dae" scale="0.1 0.1 0.1"/>
      </geometry>
      <material name="Grey"/>
    </visual>
    <collision>
      <origin rpy="0 0 0" xyz="0 0 0"/>
      <geometry name="distal_collision_geom">
        <mesh filename="/home/soumya.mondal/Desktop/Projects/Arnie/arnie/models/Arnie/meshes/F1.dae" scale="0.1 0.1 0.1"/>
      </geometry>
    </collision>
  </link>
  <joint name="LFJ1" type="revolute">
    <parent link="lfmiddle"/>
    <child link="lfdistal"/>
    <origin rpy="0 0 0" xyz="0 0 0.025"/>
    <axis xyz="1 0 0"/>
    <limit effort="100" lower="0" upper="1.57079632679" velocity="1.0"/>
    <dynamics damping="50.5"/>
  </joint>
  <link name="lftip">
    <inertial>
      <mass value="0.001"/>
      <inertia ixx="0.0" ixy="0.0" ixz="0.0" iyy="0.0" iyz="0.0" izz="0.0"/>
    </inertial>
  </link>
  <joint name="LFtip" type="fixed">
    <parent link="lfdistal"/>
    <child link="lftip"/>
    <origin rpy="0 0 0" xyz="0 0 0.026"/>
  </joint>
  <link name="thbase">
    <inertial>
      <mass value="0.010"/>
      <origin rpy="0 0 0" xyz="0 0 0"/>
      <inertia ixx="0.0" ixy="0.0" ixz="0.0" iyy="0.0" iyz="0.0" izz="0.1"/>
    </inertial>
    <visual>
      <origin rpy="0 0 0" xyz="0 0 0"/>
      <geometry name="thbase_visual">
        <box size="0.001 0.001 0.001"/>
      </geometry>
      <material name="shadow_thbase_material">
        <color rgba="0.5 0.5 0.5 1.0"/>
      </material>
    </visual>
    <collision>
      <origin rpy="0 0 0 " xyz="0 0 0"/>
      <geometry name="thbase_collision_geom">
        <box size="0.001 0.001 0.001"/>
      </geometry>
    </collision>
  </link>
  <joint name="THJ5" type="revolute">
    <parent link="palm"/>
    <child link="thbase"/>
    <origin rpy="0 0.785398163397 0" xyz="0.034 -0.0085 0.029"/>
    <axis xyz="0 0 -1.0"/>
    <limit effort="100" lower="-1.047" upper="1.047" velocity="1.0"/>
    <dynamics damping="50.5"/>
  </joint>
  <link name="thproximal">
    <inertial>
      <mass value="0.016"/>
      <origin rpy="0 0 0" xyz="0 0 0.019"/>
      <inertia ixx="0.1" ixy="0.0" ixz="0.0" iyy="0.1" iyz="0.0" izz="0.1"/>
    </inertial>
    <visual>
      <origin rpy="0 0 0" xyz="0 0 0"/>
      <geometry name="thproximal_visual">
        <mesh filename="/home/soumya.mondal/Desktop/Projects/Arnie/arnie/models/Arnie/meshes/TH3_z.dae" scale="0.1 0.1 0.1"/>
      </geometry>
      <material name="shadow_thproximal_material">
        <color rgba="0.2 0.2 0.2 1.0"/>
      </material>
    </visual>
    <collision>
      <origin rpy="0 0 0" xyz="0 0 0.019"/>
      <geometry name="thproximal_collision_geom">
        <box size="0.008 0.008 0.020"/>
      </geometry>
    </collision>
  </link>
  <joint name="THJ4" type="revolute">
    <parent link="thbase"/>
    <child link="thproximal"/>
    <origin rpy="0 0 0" xyz="0 0 0"/>
    <axis xyz="1.0 0 0"/>
    <limit effort="100" lower="0" upper="1.309" velocity="1.0"/>
    <dynamics damping="50.5"/>
  </joint>
  <link name="thhub">
    <inertial>
      <mass value="0.002"/>
      <origin rpy="0 0 0" xyz="0 0 0"/>
      <inertia ixx="0.1" ixy="0.0" ixz="0.0" iyy="0.1" iyz="0.0" izz="0.1"/>
    </inertial>
    <visual>
      <origin rpy="0 0 0" xyz="0 0 0"/>
      <geometry name="thhub_visual">
        <box size="0.001 0.001 0.001"/>
      </geometry>
      <material name="shadow_thhub_material">
        <color rgba="0.7 0.7 0.7 1.0"/>
      </material>
    </visual>
    <collision>
      <origin rpy="0 0 0 " xyz="0 0 0"/>
      <geometry name="thhub_collision_geom">
        <box size="0.001 0.001 0.001"/>
      </geometry>
    </collision>
  </link>
  <joint name="THJ3" type="revolute">
    <parent link="thproximal"/>
    <child link="thhub"/>
    <origin rpy="0 0 0" xyz="0 0 0.038"/>
    <axis xyz="1 0 0"/>
    <limit effort="100" lower="-0.2618" upper="0.2618" velocity="1.0"/>
    <dynamics damping="50.5"/>
  </joint>
  <link name="thmiddle">
    <inertial>
      <mass value="0.016"/>
      <origin rpy="0 0 0" xyz="0 0 0.016"/>
      <inertia ixx="0.1" ixy="0.0" ixz="0.0" iyy="0.1" iyz="0.0" izz="0.1"/>
    </inertial>
    <visual>
      <origin rpy="0 0 0" xyz="0 0 0"/>
      <geometry name="thmiddle_visual">
        <mesh filename="/home/soumya.mondal/Desktop/Projects/Arnie/arnie/models/Arnie/meshes/TH2_z.dae" scale="0.1 0.1 0.1"/>
      </geometry>
      <material name="shadow_thmiddle_material">
        <color rgba="0.2 0.2 0.2 1.0"/>
      </material>
    </visual>
    <collision>
      <origin rpy="0 0 0 " xyz="0 0 0.016"/>
      <geometry name="thmiddle_collision_geom">
        <box size="0.008 0.008 0.015"/>
      </geometry>
    </collision>
  </link>
  <joint name="THJ2" type="revolute">
    <parent link="thhub"/>
    <child link="thmiddle"/>
    <origin rpy="0 0 0" xyz="0 0 0"/>
    <axis xyz="0 -1 0"/>
    <limit effort="100" lower="-0.5237" upper="0.5237" velocity="1.0"/>
    <dynamics damping="50.5"/>
  </joint>
  <link name="thdistal">
    <inertial>
      <mass value="0.016"/>
      <origin rpy="0 0 0" xyz="0 0 0.01375"/>
      <inertia ixx="0.1" ixy="0.0" ixz="0.0" iyy="0.1" iyz="0.0" izz="0.1"/>
    </inertial>
    <visual>
      <origin rpy="0 0 0" xyz="0 0.002 0.0025"/>
      <geometry name="thdistal_visual">
        <mesh filename="/home/soumya.mondal/Desktop/Projects/Arnie/arnie/models/Arnie/meshes/distal_ellipsoid.dae" scale="0.1 0.1 0.1"/>
      </geometry>
      <material name="shadow_thmiddle_material">
        <color rgba="0.2 0.2 0.2 1.0"/>
      </material>
    </visual>
    <collision>
      <origin rpy="0 0 0 " xyz="0 0.002 0.0025"/>
      <geometry name="thmiddle_collision_geom">
        <mesh filename="/home/soumya.mondal/Desktop/Projects/Arnie/arnie/models/Arnie/meshes/distal_ellipsoid.dae" scale="0.1 0.1 0.1"/>
      </geometry>
    </collision>
  </link>
  <joint name="THJ1" type="revolute">
    <parent link="thmiddle"/>
    <child link="thdistal"/>
    <origin rpy="0 0 -1.570796327" xyz="0 0 0.032"/>
    <axis xyz="1 0 0"/>
    <limit effort="100" lower="0" upper="1.571" velocity="1.0"/>
    <dynamics damping="50.5"/>
  </joint>
  <link name="thtip">
    <inertial>
      <mass value="0.001"/>
      <inertia ixx="0.0" ixy="0.0" ixz="0.0" iyy="0.0" iyz="0.0" izz="0.0"/>
    </inertial>
  </link>
  <joint name="thtip" type="fixed">
    <parent link="thdistal"/>
    <child link="thtip"/>
    <origin rpy="0 0 0" xyz="0 0 0.0275"/>
  </joint>
</robot>

